Workbook

Sheet Jan
A1: date | B1: src | C1: dst | D1: did | E1: duration | F1: talk | G1: status | H1: uniqueid | I1: direction | J1: coust_center | K1: queue_name | L1: nps
A2: Fri Jan 30 2026 17:48:36 GMT-0300 (Brasilia Standard Time) | B2: 44997687156 | C2: PSYSTEM_1013 | D2: 4430265054 | E2: 458 | F2: 297 | G2: ANSWERED | H2: FlexPBX-1769806116.332400 | I2: E | J2: SUPORTE - POWER SYSTEM | K2: PSYSTEM_SUPORTE
A3: Fri Jan 30 2026 17:26:17 GMT-0300 (Brasilia Standard Time) | B3: PSYSTEM_1002 | C3: 44988067937 | E3: 142 | F3: 107 | G3: ANSWERED | H3: FlexPBX-1769804777.332386 | I3: S | J3: SUPORTE - POWER SYSTEM
A4: Fri Jan 30 2026 17:26:02 GMT-0300 (Brasilia Standard Time) | B4: PSYSTEM_1002 | C4: 44988067937 | E4: 8 | F4: 0 | G4: UNKNOWN | H4: FlexPBX-1769804762.332378 | I4: S | J4: SUPORTE - POWER SYSTEM
A5: Fri Jan 30 2026 17:18:22 GMT-0300 (Brasilia Standard Time) | B5: 44988067937 | C5: PSYSTEM_1002 | D5: 4430265054 | E5: 193 | F5: 138 | G5: ANSWERED | H5: FlexPBX-1769804302.332259 | I5: E | J5: SUPORTE - POWER SYSTEM | K5: PSYSTEM_SUPORTE
A6: Fri Jan 30 2026 17:12:18 GMT-0300 (Brasilia Standard Time) | B6: PSYSTEM_1013 | C6: 15997113760 | E6: 40 | F6: 0 | G6: UNKNOWN | H6: FlexPBX-1769803938.332251 | I6: S | J6: SUPORTE - POWER SYSTEM
A7: Fri Jan 30 2026 17:11:35 GMT-0300 (Brasilia Standard Time) | B7: PSYSTEM_1013 | C7: 15997113760 | E7: 40 | F7: 0 | G7: UNKNOWN | H7: FlexPBX-1769803895.332243 | I7: S | J7: SUPORTE - POWER SYSTEM
A8: Fri Jan 30 2026 17:02:53 GMT-0300 (Brasilia Standard Time) | B8: 4434531529 | C8: PSYSTEM_1005 | D8: 4430265054 | E8: 1179 | F8: 1136 | G8: ANSWERED | H8: FlexPBX-1769803373.332094 | I8: E | J8: SUPORTE - POWER SYSTEM | K8: PSYSTEM_SUPORTE | L8: 5
A9: Fri Jan 30 2026 16:56:11 GMT-0300 (Brasilia Standard Time) | B9: 4330333542 | C9: PSYSTEM_1002 | D9: 4430265054 | E9: 661 | F9: 631 | G9: ANSWERED | H9: FlexPBX-1769802971.332070 | I9: E | J9: SUPORTE - POWER SYSTEM | K9: PSYSTEM_SUPORTE
A10: Fri Jan 30 2026 16:45:34 GMT-0300 (Brasilia Standard Time) | B10: 4430162376 | C10: PSYSTEM_1002 | D10: 4430265054 | E10: 240 | F10: 215 | G10: ANSWERED | H10: FlexPBX-1769802334.332040 | I10: E | J10: SUPORTE - POWER SYSTEM | K10: PSYSTEM_SUPORTE | L10: 5
A11: Fri Jan 30 2026 16:38:25 GMT-0300 (Brasilia Standard Time) | B11: 62992350286 | C11: PSYSTEM_1005 | D11: 4430265054 | E11: 263 | F11: 213 | G11: ANSWERED | H11: FlexPBX-1769801905.331990 | I11: E | J11: SUPORTE - POWER SYSTEM | K11: PSYSTEM_SUPORTE | L11: 5
A12: Fri Jan 30 2026 16:20:30 GMT-0300 (Brasilia Standard Time) | B12: 12997220975 | C12: PSYSTEM_1005 | D12: 4430265054 | E12: 312 | F12: 279 | G12: ANSWERED | H12: FlexPBX-1769800830.331958 | I12: E | J12: SUPORTE - POWER SYSTEM | K12: PSYSTEM_SUPORTE | L12: 5
A13: Fri Jan 30 2026 16:13:43 GMT-0300 (Brasilia Standard Time) | B13: 93991495484 | C13: PSYSTEM_1001 | D13: 4430265054 | E13: 540 | F13: 440 | G13: ANSWERED | H13: FlexPBX-1769800423.331841 | I13: E | J13: SUPORTE - POWER SYSTEM | K13: PSYSTEM_SUPORTE | L13: 5
A14: Fri Jan 30 2026 16:08:05 GMT-0300 (Brasilia Standard Time) | B14: PSYSTEM_1004 | C14: 4430414545 | E14: 372 | F14: 355 | G14: ANSWERED | H14: FlexPBX-1769800085.331833 | I14: S | J14: SUPORTE - POWER SYSTEM
A15: Fri Jan 30 2026 16:07:58 GMT-0300 (Brasilia Standard Time) | B15: PSYSTEM_1004 | C15: 4430414545 | E15: 5 | F15: 0 | G15: UNKNOWN | H15: FlexPBX-1769800078.331825 | I15: S | J15: SUPORTE - POWER SYSTEM
A16: Fri Jan 30 2026 16:03:36 GMT-0300 (Brasilia Standard Time) | B16: 44984198651 | C16: PSYSTEM_1000 | D16: 4430265054 | E16: 680 | F16: 613 | G16: ANSWERED | H16: FlexPBX-1769799816.331749 | I16: E | J16: SUPORTE - POWER SYSTEM | K16: PSYSTEM_SUPORTE
A17: Fri Jan 30 2026 16:01:11 GMT-0300 (Brasilia Standard Time) | B17: 44997400641 | C17: PSYSTEM_1005 | D17: 4430265054 | E17: 177 | F17: 142 | G17: ANSWERED | H17: FlexPBX-1769799671.331725 | I17: E | J17: SUPORTE - POWER SYSTEM | K17: PSYSTEM_SUPORTE
A18: Fri Jan 30 2026 15:49:07 GMT-0300 (Brasilia Standard Time) | B18: 43999317663 | C18: PSYSTEM_1013 | D18: 4430265054 | E18: 301 | F18: 237 | G18: ANSWERED | H18: FlexPBX-1769798947.331637 | I18: E | J18: SUPORTE - POWER SYSTEM | K18: PSYSTEM_SUPORTE
A19: Fri Jan 30 2026 15:38:59 GMT-0300 (Brasilia Standard Time) | B19: 11965990735 | C19: PSYSTEM_1004 | D19: 4430265054 | E19: 259 | F19: 168 | G19: ANSWERED | H19: FlexPBX-1769798339.331573 | I19: E | J19: SUPORTE - POWER SYSTEM | K19: PSYSTEM_SUPORTE | L19: 5
A20: Fri Jan 30 2026 15:30:22 GMT-0300 (Brasilia Standard Time) | B20: 4432522019 | C20: PSYSTEM_1013 | D20: 4430265054 | E20: 952 | F20: 928 | G20: ANSWERED | H20: FlexPBX-1769797822.331549 | I20: E | J20: SUPORTE - POWER SYSTEM | K20: PSYSTEM_SUPORTE
A21: Fri Jan 30 2026 15:27:52 GMT-0300 (Brasilia Standard Time) | B21: 45999211357 | C21: PSYSTEM_1004 | D21: 4431268225 | E21: 588 | F21: 552 | G21: ANSWERED | H21: FlexPBX-1769797672.331533 | I21: E | J21: SUPORTE - POWER SYSTEM | K21: PSYSTEM_SUPORTE | L21: 5
A22: Fri Jan 30 2026 15:23:21 GMT-0300 (Brasilia Standard Time) | B22: 6234347959 | C22: PSYSTEM_1005 | D22: 4430265054 | E22: 812 | F22: 740 | G22: ANSWERED | H22: FlexPBX-1769797401.331462 | I22: E | J22: SUPORTE - POWER SYSTEM | K22: PSYSTEM_SUPORTE
A23: Fri Jan 30 2026 15:23:12 GMT-0300 (Brasilia Standard Time) | B23: 43991519887 | C23: PSYSTEM_1002 | D23: 4430265054 | E23: 2089 | F23: 2075 | G23: ANSWERED | H23: FlexPBX-1769797392.331449 | I23: E | J23: SUPORTE - POWER SYSTEM | K23: PSYSTEM_SUPORTE
A24: Fri Jan 30 2026 15:21:21 GMT-0300 (Brasilia Standard Time) | B24: 43991519887 | C24: PSYSTEM_1002 | D24: 4430265054 | E24: 92 | F24: 30 | G24: ANSWERED | H24: FlexPBX-1769797281.331379 | I24: E | J24: SUPORTE - POWER SYSTEM | K24: PSYSTEM_SUPORTE | M24: 1 - Sem interação
A25: Fri Jan 30 2026 15:11:24 GMT-0300 (Brasilia Standard Time) | B25: 45999211357 | C25: PSYSTEM_1004 | D25: 4431268225 | E25: 92 | F25: 1 | G25: ANSWERED | H25: FlexPBX-1769796684.331294 | I25: E | J25: SUPORTE - POWER SYSTEM | K25: PSYSTEM_SUPORTE
A26: Fri Jan 30 2026 15:09:06 GMT-0300 (Brasilia Standard Time) | B26: 44999670264 | C26: PSYSTEM_1001 | D26: 4430265054 | E26: 632 | F26: 614 | G26: ANSWERED | H26: FlexPBX-1769796546.331270 | I26: E | J26: SUPORTE - POWER SYSTEM | K26: PSYSTEM_SUPORTE | L26: 5
A27: Fri Jan 30 2026 14:42:02 GMT-0300 (Brasilia Standard Time) | B27: PSYSTEM_1005 | C27: 4431272549 | E27: 132 | F27: 131 | G27: ANSWERED | H27: FlexPBX-1769794922.331242 | I27: S | J27: SUPORTE - POWER SYSTEM
A28: Fri Jan 30 2026 14:41:37 GMT-0300 (Brasilia Standard Time) | B28: PSYSTEM_1005 | C28: 4432212549 | E28: 22 | F28: 21 | G28: ANSWERED | H28: FlexPBX-1769794897.331228 | I28: S | J28: SUPORTE - POWER SYSTEM
A29: Fri Jan 30 2026 14:34:24 GMT-0300 (Brasilia Standard Time) | B29: 1732146970 | C29: PSYSTEM_1013 | D29: 4431268225 | E29: 882 | F29: 810 | G29: ANSWERED | H29: FlexPBX-1769794464.331148 | I29: E | J29: SUPORTE - POWER SYSTEM | K29: PSYSTEM_SUPORTE
A30: Fri Jan 30 2026 14:17:39 GMT-0300 (Brasilia Standard Time) | B30: 47999115463 | C30: PSYSTEM_1002 | D30: 4430265054 | E30: 134 | F30: 98 | G30: ANSWERED | H30: FlexPBX-1769793459.331066 | I30: E | J30: SUPORTE - POWER SYSTEM | K30: PSYSTEM_SUPORTE | L30: 5
A31: Fri Jan 30 2026 14:12:04 GMT-0300 (Brasilia Standard Time) | B31: PSYSTEM_1000 | C31: 44999844110 | E31: 52 | F31: 31 | G31: ANSWERED | H31: FlexPBX-1769793124.331052 | I31: S | J31: SUPORTE - POWER SYSTEM
A32: Fri Jan 30 2026 14:05:10 GMT-0300 (Brasilia Standard Time) | B32: PSYSTEM_1000 | C32: 4430271000 | E32: 230 | F32: 224 | G32: ANSWERED | H32: FlexPBX-1769792710.331024 | I32: S | J32: SUPORTE - POWER SYSTEM
A33: Fri Jan 30 2026 14:04:26 GMT-0300 (Brasilia Standard Time) | B33: PSYSTEM_1000 | C33: 4430271000 | E33: 71 | F33: 66 | G33: ANSWERED | H33: FlexPBX-1769792666.331012 | I33: S | J33: SUPORTE - POWER SYSTEM
A34: Fri Jan 30 2026 14:03:01 GMT-0300 (Brasilia Standard Time) | B34: PSYSTEM_1000 | C34: 4430271000 | E34: 51 | F34: 45 | G34: ANSWERED | H34: FlexPBX-1769792581.330998 | I34: S | J34: SUPORTE - POWER SYSTEM
A35: Fri Jan 30 2026 13:58:33 GMT-0300 (Brasilia Standard Time) | B35: 44991116911 | C35: PSYSTEM_1005 | D35: 4430265054 | E35: 2126 | F35: 2101 | G35: ANSWERED | H35: FlexPBX-1769792313.330964 | I35: E | J35: SUPORTE - POWER SYSTEM | K35: PSYSTEM_SUPORTE | L35: 5
A36: Fri Jan 30 2026 13:56:38 GMT-0300 (Brasilia Standard Time) | B36: PSYSTEM_1000 | C36: 4430266599 | E36: 1 | F36: 0 | G36: UNKNOWN | H36: FlexPBX-1769792198.330948 | I36: S | J36: SUPORTE - POWER SYSTEM
A37: Fri Jan 30 2026 13:56:24 GMT-0300 (Brasilia Standard Time) | B37: PSYSTEM_1000 | C37: 4430266599 | E37: 1 | F37: 0 | G37: UNKNOWN | H37: FlexPBX-1769792184.330940 | I37: S | J37: SUPORTE - POWER SYSTEM
A38: Fri Jan 30 2026 13:56:12 GMT-0300 (Brasilia Standard Time) | B38: PSYSTEM_1000 | C38: 4430266599 | E38: 2 | F38: 0 | G38: UNKNOWN | H38: FlexPBX-1769792172.330932 | I38: S | J38: SUPORTE - POWER SYSTEM
A39: Fri Jan 30 2026 13:51:45 GMT-0300 (Brasilia Standard Time) | B39: 45999211357 | C39: PSYSTEM_1004 | D39: 4431268225 | E39: 1093 | F39: 992 | G39: ANSWERED | H39: FlexPBX-1769791905.330828 | I39: E | J39: SUPORTE - POWER SYSTEM | K39: PSYSTEM_SUPORTE | L39: 4
A40: Fri Jan 30 2026 13:44:42 GMT-0300 (Brasilia Standard Time) | B40: 44999147017 | C40: PSYSTEM_1004 | D40: 4430265054 | E40: 267 | F40: 157 | G40: ANSWERED | H40: FlexPBX-1769791482.330732 | I40: E | J40: SUPORTE - POWER SYSTEM | K40: PSYSTEM_SUPORTE
...

Sheet Notas Jan
A1: 1005 - Dayane | B1: 1002 - Luiz | C1: 1004 - Lukas | D1: 1013 - Lucas | E1: 1001 - Gabriel
A2: 5 | B2: 5 | C2: 5 | D2: 5 | E2: 5
A3: 3 | B3: 5 | C3: 5 | D3: 5 | E3: 5
A4: 5 | B4: 5 | C4: 5 | D4: 5 | E4: 5
A5: 5 | B5: 5 | C5: 5 | D5: 5 | E5: 5
A6: 5 | B6: 5 | C6: 5 | D6: 5 | E6: 5
A7: 5 | B7: 5 | C7: 5 | D7: 5 | E7: 5
A8: 5 | B8: 5 | C8: 5 | D8: 5 | E8: 5
A9: 5 | B9: 5 | C9: 4 | D9: 5 | E9: 4
A10: 5 | B10: 5 | C10: 5 | D10: 5 | E10: 5
A11: 5 | B11: 5 | C11: 5 | D11: 5 | E11: 5
A12: 5 | B12: 5 | C12: 5 | D12: 5 | E12: 5
A13: 5 | B13: 5 | C13: 5 | D13: 5 | E13: 5
... A62: 5 | B62: 5 | C62: 5 | D62: 5 | E62: 5
A63: 5 | B63: 5 | C63: 5
A64: 5 | B64: 5 | C64: 5
B65: 5 | C65: 5
B66: 5 | C66: 5
B67: 5 | C67: 5
B68: 5 | C68: 5
B69: 5 | C69: 5
B70: 5 | C70: 5
B71: 5 | C71: 5
B72: 5
B73: 5
B74: 4
B75: 4
B76: 5
B77: 5
B78: 5
B79: 5
B80: 5
B81: 5
B82: 4
B83: 5
... B113: 5

Sheet Nps Jan
A1: ATENDENTE | B1: QTD ATENDIMENTOS | C1: QTD AVALIADOS | D1: PERCENTUAL AVALIAÇÃO | E1: MÉDIA NOTAS | F1: DESCONTOS AVALIAÇÕES | G1: MÉDIA NOTAS FINAL | I1: PONTUAÇÃO CAIXINHA
A2: 1005 - Dayane | B2: =D15+E15+F15 -> 189 | C2: =B15+C15 -> 70 | D2: =C2/B2 -> 0.37037037 | E2: =AVERAGE('Notas Jan'!$A$2:$A$111) -> 4.8571429 | G2: =E2-F2 -> 4.8571429 | I2: =G2*C2 -> 340
A3: 1002 - Luiz | B3: =D16+E16+F16 -> 339 | C3: =B16+C16 -> 124 | D3: =C3/B3 -> 0.36578171 | E3: =AVERAGE('Notas Jan'!$B$2:$B$111) -> 4.9545455 | G3: =E3-F3 -> 4.9545455 | I3: =G3*C3 -> 614.36364
A4: 1004 - Lukas | B4: =D17+E17+F17 -> 357 | C4: =B17+C17 -> 77 | D4: =C4/B4 -> 0.21568627 | E4: =AVERAGE('Notas Jan'!$C$2:$C$111) -> 4.9714286 | G4: =E4-F4 -> 4.9714286 | I4: =G4*C4 -> 382.8
A5: 1013 - Lucas | B5: =D18+E18+F18 -> 354 | C5: =B18+C18 -> 74 | D5: =C5/B5 -> 0.20903955 | E5: =AVERAGE('Notas Jan'!$D$2:$D$111) -> 4.9016393 | G5: =E5-F5 -> 4.9016393 | I5: =G5*C5 -> 362.72131
A6: 1001 - Gabriel | B6: =D19+E19+F19 -> 325 | C6: =B19+C19 -> 76 | D6: =C6/B6 -> 0.23384615 | E6: =AVERAGE('Notas Jan'!$E$2:$E$111) -> 4.9508197 | G6: =E6-F6 -> 4.9508197 | I6: =G6*C6 -> 376.2623
A9: TOTAL | B9: =SUM(B2:B7) -> 1564 | C9: =SUM(C2:C7) -> 421 | D9: =C9/B9 -> 0.26918159 | E9: =AVERAGE(E2:E7) -> 4.9271152 | G9: =E9-F9 -> 4.9271152
A14: ATENDENTE | B14: QSA | C14: QEA | D14: TS FONE | E14: TE FONE | F14: TE WHATS | G14: WHATS AVALIADOS
A15: 1005 - Dayane | B15: =COUNTIFS(Jan!$B$2:$B$3000,"PSYSTEM_1005",Jan!$E$2:$E$3000,">100",Jan!$L$2:$L$3000,">0") -> 11 | C15: =COUNTIFS(Jan!$C$2:$C$3000,"PSYSTEM_1005",Jan!$E$2:$E$3000,">100",Jan!$L$2:$L$3000,">0")+G15 -> 59 | D15: =COUNTIFS(Jan!$B$2:$B$3000,"PSYSTEM_1005",Jan!$E$2:$E$3000,">100") -> 29 | E15: =COUNTIFS(Jan!$C$2:$C$3000,"PSYSTEM_1005",Jan!$E$2:$E$3000,">100") -> 120 | F15: 40 | G15: 7
A16: 1002 - Luiz | B16: =COUNTIFS(Jan!$B$2:$B$3000,"PSYSTEM_1002",Jan!$E$2:$E$3000,">100",Jan!$L$2:$L$3000,">0") -> 12 | C16: =COUNTIFS(Jan!$C$2:$C$3000,"PSYSTEM_1002",Jan!$E$2:$E$3000,">100",Jan!$L$2:$L$3000,">0")+G16 -> 112 | D16: =COUNTIFS(Jan!$B$2:$B$3000,"PSYSTEM_1002",Jan!$E$2:$E$3000,">100") -> 51 | E16: =COUNTIFS(Jan!$C$2:$C$3000,"PSYSTEM_1002",Jan!$E$2:$E$3000,">100") -> 215 | F16: 73 | G16: 12
A17: 1004 - Lukas | B17: =COUNTIFS(Jan!$B$2:$B$3000,"PSYSTEM_1004",Jan!$E$2:$E$3000,">100",Jan!$L$2:$L$3000,">0") -> 5 | C17: =COUNTIFS(Jan!$C$2:$C$3000,"PSYSTEM_1004",Jan!$E$2:$E$3000,">100",Jan!$L$2:$L$3000,">0")+G17 -> 72 | D17: =COUNTIFS(Jan!$B$2:$B$3000,"PSYSTEM_1004",Jan!$E$2:$E$3000,">100") -> 31 | E17: =COUNTIFS(Jan!$C$2:$C$3000,"PSYSTEM_1004",Jan!$E$2:$E$3000,">100") -> 244 | F17: 82 | G17: 7
A18: 1013 - Lucas | B18: =COUNTIFS(Jan!$B$2:$B$3000,"PSYSTEM_1013",Jan!$E$2:$E$3000,">100",Jan!$L$2:$L$3000,">0") -> 9 | C18: =COUNTIFS(Jan!$C$2:$C$3000,"PSYSTEM_1013",Jan!$E$2:$E$3000,">100",Jan!$L$2:$L$3000,">0")+G18 -> 65 | D18: =COUNTIFS(Jan!$B$2:$B$3000,"PSYSTEM_1013",Jan!$E$2:$E$3000,">100") -> 46 | E18: =COUNTIFS(Jan!$C$2:$C$3000,"PSYSTEM_1013",Jan!$E$2:$E$3000,">100") -> 217 | F18: 91 | G18: 13
A19: 1001 - Gabriel | B19: =COUNTIFS(Jan!$B$2:$B$3000,"PSYSTEM_1001",Jan!$E$2:$E$3000,">100",Jan!$L$2:$L$3000,">0") -> 5 | C19: =COUNTIFS(Jan!$C$2:$C$3000,"PSYSTEM_1001",Jan!$E$2:$E$3000,">100",Jan!$L$2:$L$3000,">0")+G19 -> 71 | D19: =COUNTIFS(Jan!$B$2:$B$3000,"PSYSTEM_1001",Jan!$E$2:$E$3000,">100") -> 46 | E19: =COUNTIFS(Jan!$C$2:$C$3000,"PSYSTEM_1001",Jan!$E$2:$E$3000,">100") -> 190 | F19: 89 | G19: 15
A21: QSA = QUANTIDADE DE SAIDAS AVALIADA
A22: QEA = QUANTIDADE DE ENTRADAS AVALIADAS
A23: TS - TOTAL DE SAIDAS
A24: TE - TOTAL DE ENTRADAS

Sheet Fev
A1: date | B1: src | C1: dst | D1: did | E1: duration | F1: talk | G1: status | H1: uniqueid | I1: direction | J1: coust_center | K1: queue_name | L1: nps
A2: 46081.444 | B2: 4435226025 | C2: 4430265054 | D2: 4430265054 | E2: 18 | F2: 17 | G2: NO ANSWER | H2: FlexPBX-1772285979.65002 | I2: E | J2: GERAL - POWER SYSTEM
A3: 46081.423 | B3: 35998295948 | C3: 4430265054 | D3: 4430265054 | E3: 18 | F3: 18 | G3: NO ANSWER | H3: FlexPBX-1772284184.64997 | I3: E | J3: GERAL - POWER SYSTEM
A4: 46080.742 | B4: 4432272377 | C4: PSYSTEM_1001 | D4: 4430265054 | E4: 421 | F4: 334 | G4: ANSWERED | H4: FlexPBX-1772225310.64939 | I4: E | J4: SUPORTE - POWER SYSTEM | K4: PSYSTEM_SUPORTE
A5: 46080.736 | B5: PSYSTEM_1013 | C5: 4432677399 | E5: 97 | F5: 0 | G5: UNKNOWN | H5: FlexPBX-1772224755.64931 | I5: S | J5: SUPORTE - POWER SYSTEM
A6: 46080.735 | B6: PSYSTEM_1013 | C6: 4432677399 | E6: 5 | F6: 0 | G6: UNKNOWN | H6: FlexPBX-1772224747.64923 | I6: S | J6: SUPORTE - POWER SYSTEM
A7: 46080.732 | B7: PSYSTEM_1002 | C7: 93995233136 | E7: 3 | F7: 0 | G7: UNKNOWN | H7: FlexPBX-1772224453.64888 | I7: S | J7: SUPORTE - POWER SYSTEM
A8: 46080.732 | B8: PSYSTEM_1002 | C8: 93995233136 | E8: 12 | F8: 0 | G8: UNKNOWN | H8: FlexPBX-1772224428.64864 | I8: S | J8: SUPORTE - POWER SYSTEM
A9: 46080.731 | B9: 41996175686 | C9: PSYSTEM_1005 | D9: 4430265054 | E9: 256 | F9: 146 | G9: ANSWERED | H9: FlexPBX-1772224367.64821 | I9: E | J9: SUPORTE - POWER SYSTEM | K9: PSYSTEM_SUPORTE | L9: 5
A10: 46080.729 | B10: 44997749003 | C10: 4430265054 | D10: 4430265054 | E10: 73 | F10: 72 | G10: NO ANSWER | H10: FlexPBX-1772224177.64776 | I10: E | J10: GERAL - POWER SYSTEM | K10: PSYSTEM_SUPORTE
A11: 46080.72 | B11: PSYSTEM_1002 | C11: 44999807675 | E11: 9 | F11: 0 | G11: UNKNOWN | H11: FlexPBX-1772223408.64752 | I11: S | J11: SUPORTE - POWER SYSTEM
A12: 46080.72 | B12: PSYSTEM_1005 | C12: 44997311122 | E12: 40 | F12: 27 | G12: ANSWERED | H12: FlexPBX-1772223403.64748 | I12: S | J12: SUPORTE - POWER SYSTEM
A13: 46080.72 | B13: PSYSTEM_1002 | C13: 44999807675 | E13: 15 | F13: 0 | G13: UNKNOWN | H13: FlexPBX-1772223381.64740 | I13: S | J13: SUPORTE - POWER SYSTEM
A14: 46080.718 | B14: PSYSTEM_1002 | C14: 4432226677 | E14: 5 | F14: 0 | G14: UNKNOWN | H14: FlexPBX-1772223276.64728 | I14: S | J14: SUPORTE - POWER SYSTEM
A15: 46080.716 | B15: PSYSTEM_1013 | C15: 4436351818 | E15: 407 | F15: 389 | G15: ANSWERED | H15: FlexPBX-1772223052.64706 | I15: S | J15: SUPORTE - POWER SYSTEM
A16: 46080.716 | B16: PSYSTEM_1013 | C16: 4436351818 | E16: 1 | F16: 0 | G16: UNKNOWN | H16: FlexPBX-1772223048.64698 | I16: S | J16: SUPORTE - POWER SYSTEM
A17: 46080.716 | B17: PSYSTEM_1013 | C17: 4436351818 | E17: 4 | F17: 0 | G17: UNKNOWN | H17: FlexPBX-1772223043.64690 | I17: S | J17: SUPORTE - POWER SYSTEM
A18: 46080.716 | B18: PSYSTEM_1013 | C18: 4436351818 | E18: 6 | F18: 0 | G18: UNKNOWN | H18: FlexPBX-1772223037.64682 | I18: S | J18: SUPORTE - POWER SYSTEM
A19: 46080.715 | B19: PSYSTEM_1013 | C19: 44999689445 | E19: 35 | F19: 0 | G19: UNKNOWN | H19: FlexPBX-1772222952.64668 | I19: S | J19: SUPORTE - POWER SYSTEM
A20: 46080.714 | B20: PSYSTEM_1004 | C20: 4430191465 | E20: 66 | F20: 46 | G20: ANSWERED | H20: FlexPBX-1772222906.64650 | I20: S | J20: SUPORTE - POWER SYSTEM
A21: 46080.714 | B21: PSYSTEM_1004 | C21: 4430191465 | E21: 2 | F21: 0 | G21: UNKNOWN | H21: FlexPBX-1772222902.64642 | I21: S | J21: SUPORTE - POWER SYSTEM
A22: 46080.714 | B22: PSYSTEM_1013 | C22: 44999689445 | E22: 55 | F22: 19 | G22: ANSWERED | H22: FlexPBX-1772222894.64638 | I22: S | J22: SUPORTE - POWER SYSTEM
A23: 46080.711 | B23: 1128897100 | C23: PSYSTEM_1000 | D23: 4430265054 | E23: 129 | F23: 103 | G23: ANSWERED | H23: FlexPBX-1772222635.64584 | I23: E | J23: SUPORTE - POWER SYSTEM | K23: PSYSTEM_SUPORTE
A24: 46080.71 | B24: 1733231449 | C24: PSYSTEM_1002 | D24: 4430265054 | E24: 227 | F24: 195 | G24: ANSWERED | H24: FlexPBX-1772222523.64568 | I24: E | J24: SUPORTE - POWER SYSTEM | K24: PSYSTEM_SUPORTE | L24: 5
A25: 46080.702 | B25: 44997749003 | C25: PSYSTEM_1000 | D25: 4430265054 | E25: 132 | F25: 131 | G25: ANSWERED | H25: FlexPBX-1772221849.64508 | I25: E | J25: SUPORTE - POWER SYSTEM | K25: PSYSTEM_SUPORTE
A26: 46080.702 | B26: 96981080303 | C26: PSYSTEM_1004 | D26: 4430265054 | E26: 607 | F26: 547 | G26: ANSWERED | H26: FlexPBX-1772221837.64505 | I26: E | J26: SUPORTE - POWER SYSTEM | K26: PSYSTEM_SUPORTE
A27: 46080.694 | B27: 11916079448 | C27: PSYSTEM_1013 | D27: 4430265054 | E27: 1078 | F27: 954 | G27: ANSWERED | H27: FlexPBX-1772221187.64421 | I27: E | J27: SUPORTE - POWER SYSTEM | K27: PSYSTEM_SUPORTE | L27: 5
A28: 46080.693 | B28: PSYSTEM_1000 | C28: 4430182968 | E28: 298 | F28: 291 | G28: ANSWERED | H28: FlexPBX-1772221044.64409 | I28: S | J28: SUPORTE - POWER SYSTEM
A29: 46080.692 | B29: PSYSTEM_1000 | C29: 4430182968 | E29: 2 | F29: 0 | G29: UNKNOWN | H29: FlexPBX-1772221031.64401 | I29: S | J29: SUPORTE - POWER SYSTEM
A30: 46080.692 | B30: PSYSTEM_1000 | C30: 4030182968 | E30: 3 | F30: 0 | G30: UNKNOWN | H30: FlexPBX-1772221025.64393 | I30: S | J30: SUPORTE - POWER SYSTEM
A31: 46080.69 | B31: 4334226481 | C31: PSYSTEM_1013 | D31: 4430265054 | E31: 374 | F31: 279 | G31: ANSWERED | H31: FlexPBX-1772220814.64329 | I31: E | J31: SUPORTE - POWER SYSTEM | K31: PSYSTEM_SUPORTE
A32: 46080.688 | B32: 4439001698 | C32: PSYSTEM_1001 | D32: 4430265054 | E32: 2075 | F32: 2016 | G32: ANSWERED | H32: FlexPBX-1772220621.64265 | I32: E | J32: SUPORTE - POWER SYSTEM | K32: PSYSTEM_SUPORTE | L32: 5
A33: 46080.685 | B33: 44999215148 | C33: PSYSTEM_1001 | D33: 4430265054 | E33: 139 | F33: 44 | G33: ANSWERED | H33: FlexPBX-1772220350.64141 | I33: E | J33: SUPORTE - POWER SYSTEM | K33: PSYSTEM_SUPORTE
A34: 46080.682 | B34: 44999215148 | C34: PSYSTEM_1002 | D34: 4430265054 | E34: 155 | F34: 132 | G34: ANSWERED | H34: FlexPBX-1772220122.64111 | I34: E | J34: SUPORTE - POWER SYSTEM | K34: PSYSTEM_SUPORTE
A35: 46080.678 | B35: PSYSTEM_1004 | C35: 44988067937 | E35: 39 | F35: 0 | G35: UNKNOWN | H35: FlexPBX-1772219796.64085 | I35: S | J35: SUPORTE - POWER SYSTEM
A36: 46080.678 | B36: PSYSTEM_1004 | C36: 44988067937 | E36: 5 | F36: 0 | G36: UNKNOWN | H36: FlexPBX-1772219790.64077 | I36: S | J36: SUPORTE - POWER SYSTEM
A37: 46080.676 | B37: 12997220975 | C37: PSYSTEM_1013 | D37: 4430265054 | E37: 506 | F37: 424 | G37: ANSWERED | H37: FlexPBX-1772219568.64003 | I37: E | J37: SUPORTE - POWER SYSTEM | K37: PSYSTEM_SUPORTE
A38: 46080.672 | B38: 6234347959 | C38: PSYSTEM_1001 | D38: 4430265054 | E38: 724 | F38: 588 | G38: ANSWERED | H38: FlexPBX-1772219260.63873 | I38: E | J38: SUPORTE - POWER SYSTEM | K38: PSYSTEM_SUPORTE
A39: 46080.672 | B39: 4134348913 | C39: 4531273172 | D39: 4531273172 | E39: 9 | F39: 8 | G39: NO ANSWER | H39: FlexPBX-1772219234.63868 | I39: E | J39: GERAL - POWER SYSTEM
A40: 46080.665 | B40: 4432325260 | C40: 4430265054 | D40: 4430265054 | E40: 6 | F40: 6 | G40: NO ANSWER | H40: FlexPBX-1772218648.63813 | I40: E | J40: GERAL - POWER SYSTEM
...

Sheet Notas Fev
A1: 1005 - Dayane | B1: 1002 - Luiz | C1: 1004 - Lukas | D1: 1013 - Lucas | E1: 1001 - Gabriel
A2: 5 | B2: 5 | C2: 5 | D2: 5 | E2: 5
A3: 5 | B3: 5 | C3: 5 | D3: 5 | E3: 5
A4: 5 | B4: 5 | C4: 5 | D4: 5 | E4: 5
A5: 5 | B5: 5 | C5: 5 | D5: 5 | E5: 5
A6: 5 | B6: 5 | C6: 5 | D6: 5 | E6: 5
A7: 5 | B7: 5 | C7: 5 | D7: 5 | E7: 5
A8: 5 | B8: 5 | C8: 5 | D8: 5 | E8: 5
A9: 5 | B9: 5 | C9: 5 | D9: 5 | E9: 5
A10: 5 | B10: 5 | C10: 5 | D10: 5 | E10: 5
A11: 5 | B11: 5 | C11: 5 | D11: 5 | E11: 5
A12: 5 | B12: 5 | C12: 5 | D12: 5 | E12: 5
A13: 5 | B13: 5 | C13: 5 | D13: 5 | E13: 5
... A63: 5 | B63: 5 | C63: 5 | D63: 5 | E63: 5
A64: 5 | B64: 5 | C64: 5 | E64: 5
A65: 5 | B65: 5 | C65: 5 | E65: 5
A66: 5 | B66: 5 | C66: 5 | E66: 5
A67: 5 | B67: 5 | E67: 5
A68: 5 | B68: 5 | E68: 5
A69: 5 | B69: 3 | E69: 5
A70: 5 | B70: 5 | E70: 5
A71: 5 | B71: 4 | E71: 5
A72: 5 | B72: 5 | E72: 5
A73: 5 | B73: 5 | E73: 5
A74: 5 | B74: 5 | E74: 5
A75: 5 | B75: 5 | E75: 5
A76: 5 | B76: 5 | E76: 5
A77: 5 | B77: 5
A78: 5 | B78: 5
A79: 5 | B79: 5
A80: 5 | B80: 5
A81: 5 | B81: 5
A82: 5 | B82: 5
A83: 5 | B83: 5
A84: 5 | B84: 5
A85: 5 | B85: 5
A86: 5 | B86: 4
A87: 5 | B87: 5
A88: 5 | B88: 5
... A122: 5 | B122: 5
...

Sheet Nps Fev
A1: ATENDENTE | B1: QTD ATENDIMENTOS | C1: QTD AVALIADOS | D1: PERCENTUAL AVALIAÇÃO | E1: MÉDIA NOTAS | F1: DESCONTOS AVALIAÇÕES | G1: MÉDIA NOTAS FINAL | I1: PONTUAÇÃO CAIXINHA
A2: 1005 - Dayane | B2: =D15+E15+F15 -> 453 | C2: =B15+C15 -> 137 | D2: =C2/B2 -> 0.30242826 | E2: =AVERAGE('Notas Fev'!$A$2:$A$200) -> 4.921875 | G2: =E2-F2 -> 4.921875 | I2: =G2*C2 -> 674.29688
A3: 1002 - Luiz | B3: =D16+E16+F16 -> 361 | C3: =B16+C16 -> 129 | D3: =C3/B3 -> 0.35734072 | E3: =AVERAGE('Notas Fev'!$B$2:$B$200) -> 4.9173554 | G3: =E3-F3 -> 4.9173554 | I3: =G3*C3 -> 634.33884
A4: 1004 - Lukas | B4: =D17+E17+F17 -> 414 | C4: =B17+C17 -> 76 | D4: =C4/B4 -> 0.18357488 | E4: =AVERAGE('Notas Fev'!$C$2:$C$200) -> 4.9230769 | G4: =E4-F4 -> 4.9230769 | I4: =G4*C4 -> 374.15385
A5: 1013 - Lucas | B5: =D18+E18+F18 -> 397 | C5: =B18+C18 -> 79 | D5: =C5/B5 -> 0.19899244 | E5: =AVERAGE('Notas Fev'!$D$2:$D$200) -> 4.983871 | G5: =E5-F5 -> 4.983871 | I5: =G5*C5 -> 393.72581
A6: 1001 - Gabriel | B6: =D19+E19+F19 -> 396 | C6: =B19+C19 -> 93 | D6: =C6/B6 -> 0.23484848 | E6: =AVERAGE('Notas Fev'!$E$2:$E$200) -> 5 | G6: =E6-F6 -> 5 | I6: =G6*C6 -> 465
A9: TOTAL | B9: =SUM(B2:B7) -> 2021 | C9: =SUM(C2:C7) -> 514 | D9: =C9/B9 -> 0.25432954 | E9: =AVERAGE(E2:E7) -> 4.9492357 | G9: =E9-F9 -> 4.9492357
A14: ATENDENTE | B14: QSA | C14: QEA | D14: TS FONE | E14: TE FONE | F14: TE WHATS | G14: WHATS AVALIADOS
A15: 1005 - Dayane | B15: =COUNTIFS(Fev!$B$2:$B$4000,"PSYSTEM_1005",Fev!$E$2:$E$4000,">100",Fev!$L$2:$L$4000,">0") -> 16 | C15: =COUNTIFS(Fev!$C$2:$C$4000,"PSYSTEM_1005",Fev!$E$2:$E$4000,">100",Fev!$L$2:$L$4000,">0")+G15 -> 121 | D15: =COUNTIFS(Fev!$B$2:$B$4000,"PSYSTEM_1005",Fev!$E$2:$E$4000,">100") -> 76 | E15: =COUNTIFS(Fev!$C$2:$C$4000,"PSYSTEM_1005",Fev!$E$2:$E$4000,">100") -> 303 | F15: 74 | G15: 9
A16: 1002 - Luiz | B16: =COUNTIFS(Fev!$B$2:$B$4000,"PSYSTEM_1002",Fev!$E$2:$E$4000,">100",Fev!$L$2:$L$4000,">0") -> 16 | C16: =COUNTIFS(Fev!$C$2:$C$4000,"PSYSTEM_1002",Fev!$E$2:$E$4000,">100",Fev!$L$2:$L$4000,">0")+G16 -> 113 | D16: =COUNTIFS(Fev!$B$2:$B$4000,"PSYSTEM_1002",Fev!$E$2:$E$4000,">100") -> 49 | E16: =COUNTIFS(Fev!$C$2:$C$4000,"PSYSTEM_1002",Fev!$E$2:$E$4000,">100") -> 237 | F16: 75 | G16: 8
A17: 1004 - Lukas | B17: =COUNTIFS(Fev!$B$2:$B$4000,"PSYSTEM_1004",Fev!$E$2:$E$4000,">100",Fev!$L$2:$L$4000,">0") -> 3 | C17: =COUNTIFS(Fev!$C$2:$C$4000,"PSYSTEM_1004",Fev!$E$2:$E$4000,">100",Fev!$L$2:$L$4000,">0")+G17 -> 73 | D17: =COUNTIFS(Fev!$B$2:$B$4000,"PSYSTEM_1004",Fev!$E$2:$E$4000,">100") -> 41 | E17: =COUNTIFS(Fev!$C$2:$C$4000,"PSYSTEM_1004",Fev!$E$2:$E$4000,">100") -> 299 | F17: 74 | G17: 11
A18: 1013 - Lucas | B18: =COUNTIFS(Fev!$B$2:$B$4000,"PSYSTEM_1013",Fev!$E$2:$E$4000,">100",Fev!$L$2:$L$4000,">0") -> 7 | C18: =COUNTIFS(Fev!$C$2:$C$4000,"PSYSTEM_1013",Fev!$E$2:$E$4000,">100",Fev!$L$2:$L$4000,">0")+G18 -> 72 | D18: =COUNTIFS(Fev!$B$2:$B$4000,"PSYSTEM_1013",Fev!$E$2:$E$4000,">100") -> 40 | E18: =COUNTIFS(Fev!$C$2:$C$4000,"PSYSTEM_1013",Fev!$E$2:$E$4000,">100") -> 245 | F18: 112 | G18: 17
A19: 1001 - Gabriel | B19: =COUNTIFS(Fev!$B$2:$B$4000,"PSYSTEM_1001",Fev!$E$2:$E$4000,">100",Fev!$L$2:$L$4000,">0") -> 7 | C19: =COUNTIFS(Fev!$C$2:$C$4000,"PSYSTEM_1001",Fev!$E$2:$E$4000,">100",Fev!$L$2:$L$4000,">0")+G19 -> 86 | D19: =COUNTIFS(Fev!$B$2:$B$4000,"PSYSTEM_1001",Fev!$E$2:$E$4000,">100") -> 38 | E19: =COUNTIFS(Fev!$C$2:$C$4000,"PSYSTEM_1001",Fev!$E$2:$E$4000,">100") -> 235 | F19: 123 | G19: 18
A21: QSA = QUANTIDADE DE SAIDAS AVALIADA
A22: QEA = QUANTIDADE DE ENTRADAS AVALIADAS
A23: TS - TOTAL DE SAIDAS
A24: TE - TOTAL DE ENTRADAS

Sheet Mar
A1: date | B1: src | C1: dst | D1: did | E1: duration | F1: talk | G1: status | H1: uniqueid | I1: direction | J1: coust_center | K1: queue_name | L1: nps
A2: 46112.726 | B2: 44999680829 | C2: PSYSTEM_1002 | D2: 4431268225 | E2: 392 | F2: 227 | G2: ANSWERED | H2: FlexPBX-1774988752.159687 | I2: E | J2: SUPORTE - POWER SYSTEM | K2: PSYSTEM_SUPORTE | L2: 5
A3: 46112.723 | B3: 4330333542 | C3: PSYSTEM_1005 | D3: 4430265054 | E3: 1566 | F3: 1485 | G3: ANSWERED | H3: FlexPBX-1774988501.159613 | I3: E | J3: SUPORTE - POWER SYSTEM | K3: PSYSTEM_SUPORTE | L3: 5
A4: 46112.718 | B4: 77999014770 | C4: PSYSTEM_1001 | D4: 4430265054 | E4: 574 | F4: 509 | G4: ANSWERED | H4: FlexPBX-1774988061.159555 | I4: E | J4: SUPORTE - POWER SYSTEM | K4: PSYSTEM_SUPORTE
A5: 46112.713 | B5: 44988255390 | C5: PSYSTEM_1005 | D5: 4430265054 | E5: 592 | F5: 472 | G5: ANSWERED | H5: FlexPBX-1774987611.159457 | I5: E | J5: SUPORTE - POWER SYSTEM | K5: PSYSTEM_SUPORTE
A6: 46112.708 | B6: 91985176746 | C6: PSYSTEM_1004 | D6: 4430265054 | E6: 523 | F6: 479 | G6: ANSWERED | H6: FlexPBX-1774987166.159421 | I6: E | J6: SUPORTE - POWER SYSTEM | K6: PSYSTEM_SUPORTE | L6: 5
A7: 46112.705 | B7: 43984996095 | C7: PSYSTEM_1002 | D7: 4430265054 | E7: 1105 | F7: 947 | G7: ANSWERED | H7: FlexPBX-1774986954.159277 | I7: E | J7: SUPORTE - POWER SYSTEM | K7: PSYSTEM_SUPORTE
A8: 46112.702 | B8: PSYSTEM_1005 | C8: 44999647912 | E8: 82 | F8: 77 | G8: ANSWERED | H8: FlexPBX-1774986641.159261 | I8: S | J8: SUPORTE - POWER SYSTEM
A9: 46112.702 | B9: PSYSTEM_1005 | C9: 44999647912 | E9: 25 | F9: 25 | G9: ANSWERED | H9: FlexPBX-1774986624.159249 | I9: S | J9: SUPORTE - POWER SYSTEM
A10: 46112.699 | B10: 44999647912 | C10: PSYSTEM_1005 | D10: 4430265054 | E10: 147 | F10: 104 | G10: ANSWERED | H10: FlexPBX-1774986370.159199 | I10: E | J10: SUPORTE - POWER SYSTEM | K10: PSYSTEM_SUPORTE
A11: 46112.698 | B11: 4121410323 | C11: PSYSTEM_1005 | D11: 4531273168 | E11: 47 | F11: 11 | G11: ANSWERED | H11: FlexPBX-1774986318.159169 | I11: E | J11: SUPORTE - POWER SYSTEM | K11: PSYSTEM_SUPORTE
A12: 46112.689 | B12: 4133491428 | C12: PSYSTEM_1001 | D12: 4430265054 | E12: 678 | F12: 639 | G12: ANSWERED | H12: FlexPBX-1774985498.159121 | I12: E | J12: SUPORTE - POWER SYSTEM | K12: PSYSTEM_SUPORTE
A13: 46112.686 | B13: 4432321232 | C13: PSYSTEM_1005 | D13: 4430265054 | E13: 487 | F13: 459 | G13: ANSWERED | H13: FlexPBX-1774985249.159097 | I13: E | J13: SUPORTE - POWER SYSTEM | K13: PSYSTEM_SUPORTE | L13: 5
A14: 46112.682 | B14: PSYSTEM_1002 | C14: 4436351414 | E14: 171 | F14: 160 | G14: ANSWERED | H14: FlexPBX-1774984957.159083 | I14: S | J14: SUPORTE - POWER SYSTEM
A15: 46112.678 | B15: PSYSTEM_1013 | C15: 44998782223 | E15: 271 | F15: 256 | G15: ANSWERED | H15: FlexPBX-1774984600.159061 | I15: S | J15: SUPORTE - POWER SYSTEM
A16: 46112.678 | B16: PSYSTEM_1013 | C16: 44998782223 | E16: 25 | F16: 25 | G16: ANSWERED | H16: FlexPBX-1774984595.159045 | I16: S | J16: SUPORTE - POWER SYSTEM
A17: 46112.678 | B17: PSYSTEM_1005 | C17: 44999147706 | E17: 63 | F17: 37 | G17: ANSWERED | H17: FlexPBX-1774984574.159041 | I17: S | J17: SUPORTE - POWER SYSTEM
A18: 46112.678 | B18: PSYSTEM_1005 | C18: 44999147706 | E18: 18 | F18: 0 | G18: UNKNOWN | H18: FlexPBX-1774984554.159033 | I18: S | J18: SUPORTE - POWER SYSTEM
A19: 46112.677 | B19: PSYSTEM_1005 | C19: 44999488286 | E19: 44 | F19: 38 | G19: ANSWERED | H19: FlexPBX-1774984470.159019 | I19: S | J19: SUPORTE - POWER SYSTEM
A20: 46112.671 | B20: PSYSTEM_1013 | C20: 44998782223 | E20: 26 | F20: 25 | G20: ANSWERED | H20: FlexPBX-1774984014.158976 | I20: S | J20: SUPORTE - POWER SYSTEM
A21: 46112.67 | B21: 44999743444 | C21: PSYSTEM_1001 | D21: 4430265054 | E21: 264 | F21: 164 | G21: ANSWERED | H21: FlexPBX-1774983917.158909 | I21: E | J21: SUPORTE - POWER SYSTEM | K21: PSYSTEM_SUPORTE
A22: 46112.666 | B22: PSYSTEM_1009 | C22: 4334232912 | E22: 129 | F22: 117 | G22: ANSWERED | H22: FlexPBX-1774983551.158895 | I22: S | J22: COMERCIAL - POWER SYSTEM
A23: 46112.665 | B23: PSYSTEM_1004 | C23: 44997235101 | E23: 17 | F23: 0 | G23: UNKNOWN | H23: FlexPBX-1774983455.158796 | I23: S | J23: SUPORTE - POWER SYSTEM
A24: 46112.663 | B24: 44998782223 | C24: PSYSTEM_1002 | D24: 4430265054 | E24: 969 | F24: 733 | G24: ANSWERED | H24: FlexPBX-1774983292.158685 | I24: E | J24: SUPORTE - POWER SYSTEM | K24: PSYSTEM_SUPORTE
A25: 46112.661 | B25: PSYSTEM_1008 | C25: 6530267073 | E25: 20 | F25: 16 | G25: ANSWERED | H25: FlexPBX-1774983147.158665 | I25: S | J25: COMERCIAL - POWER SYSTEM
A26: 46112.661 | B26: PSYSTEM_1008 | C26: 43991039853 | E26: 14 | F26: 0 | G26: UNKNOWN | H26: FlexPBX-1774983086.158657 | I26: S | J26: COMERCIAL - POWER SYSTEM
A27: 46112.66 | B27: PSYSTEM_1008 | C27: 61993321670 | E27: 15 | F27: 6 | G27: ANSWERED | H27: FlexPBX-1774983052.158626 | I27: S | J27: COMERCIAL - POWER SYSTEM
A28: 46112.66 | B28: 44997235101 | C28: PSYSTEM_1004 | D28: 4430265054 | E28: 441 | F28: 397 | G28: ANSWERED | H28: FlexPBX-1774983041.158623 | I28: E | J28: SUPORTE - POWER SYSTEM | K28: PSYSTEM_SUPORTE
A29: 46112.658 | B29: PSYSTEM_1008 | C29: 73999255838 | E29: 34 | F29: 13 | G29: ANSWERED | H29: FlexPBX-1774982893.158597 | I29: S | J29: COMERCIAL - POWER SYSTEM
A30: 46112.657 | B30: PSYSTEM_1008 | C30: 67998227628 | E30: 9 | F30: 2 | G30: ANSWERED | H30: FlexPBX-1774982790.158577 | I30: S | J30: COMERCIAL - POWER SYSTEM
A31: 46112.656 | B31: PSYSTEM_1008 | C31: 51995665376 | E31: 17 | F31: 0 | G31: UNKNOWN | H31: FlexPBX-1774982719.158567 | I31: S | J31: COMERCIAL - POWER SYSTEM
A32: 46112.655 | B32: PSYSTEM_1008 | C32: 63991078032 | E32: 10 | F32: 0 | G32: UNKNOWN | H32: FlexPBX-1774982585.158555 | I32: S | J32: COMERCIAL - POWER SYSTEM
A33: 46112.652 | B33: 1128787060 | C33: PSYSTEM_1004 | D33: 4430265054 | E33: 467 | F33: 440 | G33: ANSWERED | H33: FlexPBX-1774982362.158524 | I33: E | J33: SUPORTE - POWER SYSTEM | K33: PSYSTEM_COMERCIAL
A34: 46112.651 | B34: 44998782223 | C34: PSYSTEM_1013 | D34: 4430265054 | E34: 990 | F34: 895 | G34: ANSWERED | H34: FlexPBX-1774982279.158511 | I34: E | J34: SUPORTE - POWER SYSTEM | K34: PSYSTEM_SUPORTE
A35: 46112.648 | B35: 4432226677 | C35: PSYSTEM_1000 | D35: 4430265054 | E35: 150 | F35: 100 | G35: ANSWERED | H35: FlexPBX-1774982005.158487 | I35: E | J35: SUPORTE - POWER SYSTEM | K35: PSYSTEM_SUPORTE
A36: 46112.647 | B36: 44999844110 | C36: PSYSTEM_1004 | D36: 4430265054 | E36: 504 | F36: 456 | G36: ANSWERED | H36: FlexPBX-1774981905.158475 | I36: E | J36: SUPORTE - POWER SYSTEM | K36: PSYSTEM_SUPORTE
A37: 46112.646 | B37: 44988255390 | C37: PSYSTEM_1005 | D37: 4430265054 | E37: 1095 | F37: 1043 | G37: ANSWERED | H37: FlexPBX-1774981828.158442 | I37: E | J37: SUPORTE - POWER SYSTEM | K37: PSYSTEM_SUPORTE
A38: 46112.646 | B38: 4430414545 | C38: PSYSTEM_1001 | D38: 4430265054 | E38: 1117 | F38: 1099 | G38: ANSWERED | H38: FlexPBX-1774981816.158439 | I38: E | J38: SUPORTE - POWER SYSTEM | K38: PSYSTEM_SUPORTE
A39: 46112.643 | B39: 44988255390 | C39: 4430265054 | D39: 4430265054 | E39: 52 | F39: 52 | G39: NO ANSWER | H39: FlexPBX-1774981595.158410 | I39: E | J39: GERAL - POWER SYSTEM | K39: PSYSTEM_SUPORTE
A40: 46112.64 | B40: 4121418115 | C40: PSYSTEM_1005 | D40: 4531273158 | E40: 45 | F40: 9 | G40: ANSWERED | H40: FlexPBX-1774981278.158388 | I40: E | J40: SUPORTE - POWER SYSTEM | K40: PSYSTEM_SUPORTE
...

Sheet Notas Mar
A1: 1005 - Dayane | B1: 1002 - Luiz | C1: 1004 - Lukas | D1: 1013 - Lucas | E1: 1001 - Gabriel
A2: 5 | B2: 5 | C2: 5 | D2: 5 | E2: 5
A3: 5 | B3: 5 | C3: 5 | D3: 5 | E3: 5
A4: 5 | B4: 5 | C4: 5 | D4: 5 | E4: 5
A5: 4 | B5: 5 | C5: 5 | D5: 5 | E5: 5
A6: 5 | B6: 5 | C6: 5 | D6: 5 | E6: 5
A7: 5 | B7: 5 | C7: 5 | D7: 5 | E7: 5
A8: 5 | B8: 5 | C8: 5 | D8: 5 | E8: 5
A9: 5 | B9: 5 | C9: 5 | D9: 4 | E9: 5
A10: 5 | B10: 5 | C10: 4 | D10: 5 | E10: 5
A11: 5 | B11: 5 | C11: 5 | D11: 5 | E11: 5
A12: 5 | B12: 4 | C12: 5 | D12: 5 | E12: 5
A13: 5 | B13: 5 | C13: 5 | D13: 5 | E13: 5
... A55: 5 | B55: 5 | C55: 5 | D55: 5 | E55: 5
A56: 5 | B56: 5 | C56: 5 | E56: 5
A57: 5 | B57: 5 | C57: 5 | E57: 5
A58: 5 | B58: 5 | C58: 5 | E58: 5
A59: 5 | B59: 5 | C59: 5 | E59: 3
A60: 5 | B60: 5 | C60: 5 | E60: 5
A61: 5 | B61: 5 | C61: 5
A62: 5 | B62: 5 | C62: 5
A63: 5 | B63: 5 | C63: 5
A64: 5 | B64: 5 | C64: 5
A65: 5 | B65: 5 | C65: 5
A66: 5 | B66: 5
A67: 5 | B67: 5
A68: 5 | B68: 5
A69: 5 | B69: 5
A70: 5 | B70: 5
A71: 5 | B71: 5
A72: 5 | B72: 5
A73: 5 | B73: 5
A74: 5 | B74: 5
A75: 5 | B75: 5
A76: 5 | B76: 5
A77: 5 | B77: 5
... A114: 5 | B114: 5
B115: 5

Sheet Nps Mar
A1: ATENDENTE | B1: QTD ATENDIMENTOS | C1: QTD AVALIADOS | D1: PERCENTUAL AVALIAÇÃO | E1: MÉDIA NOTAS | F1: DESCONTOS AVALIAÇÕES | G1: MÉDIA NOTAS FINAL | I1: PONTUAÇÃO CAIXINHA
A2: 1005 - Dayane | B2: =D15+E15+F15 -> 453 | C2: =B15+C15 -> 120 | D2: =C2/B2 -> 0.26490066 | E2: =AVERAGE('Notas Mar'!$A$2:$A$200) -> 4.8938053 | G2: =E2-F2 -> 4.8938053 | I2: =G2*C2 -> 587.25664
A3: 1002 - Luiz | B3: =D16+E16+F16 -> 380 | C3: =B16+C16 -> 125 | D3: =C3/B3 -> 0.32894737 | E3: =AVERAGE('Notas Mar'!$B$2:$B$200) -> 4.9298246 | G3: =E3-F3 -> 4.9298246 | I3: =G3*C3 -> 616.22807
A4: 1004 - Lukas | B4: =D17+E17+F17 -> 405 | C4: =B17+C17 -> 75 | D4: =C4/B4 -> 0.18518519 | E4: =AVERAGE('Notas Mar'!$C$2:$C$200) -> 4.984375 | G4: =E4-F4 -> 4.984375 | I4: =G4*C4 -> 373.82812
A5: 1013 - Lucas | B5: =D18+E18+F18 -> 391 | C5: =B18+C18 -> 67 | D5: =C5/B5 -> 0.1713555 | E5: =AVERAGE('Notas Mar'!$D$2:$D$200) -> 4.9259259 | G5: =E5-F5 -> 4.9259259 | I5: =G5*C5 -> 330.03704
A6: 1001 - Gabriel | B6: =D19+E19+F19 -> 382 | C6: =B19+C19 -> 78 | D6: =C6/B6 -> 0.20418848 | E6: =AVERAGE('Notas Mar'!$E$2:$E$200) -> 4.9661017 | G6: =E6-F6 -> 4.9661017 | I6: =G6*C6 -> 387.35593
A9: TOTAL | B9: =SUM(B2:B7) -> 2011 | C9: =SUM(C2:C7) -> 465 | D9: =C9/B9 -> 0.23122824 | E9: =AVERAGE(E2:E7) -> 4.9400065 | G9: =E9-F9 -> 4.9400065
A14: ATENDENTE | B14: QSA | C14: QEA | D14: TS FONE | E14: TE FONE | F14: TE WHATS | G14: WHATS AVALIADOS
A15: 1005 - Dayane | B15: =COUNTIFS(Mar!$B$2:$B$4000,"PSYSTEM_1005",Mar!$E$2:$E$4000,">100",Mar!$L$2:$L$4000,">0") -> 12 | C15: =COUNTIFS(Mar!$C$2:$C$4000,"PSYSTEM_1005",Mar!$E$2:$E$4000,">100",Mar!$L$2:$L$4000,">0")+G15 -> 108 | D15: =COUNTIFS(Mar!$B$2:$B$4000,"PSYSTEM_1005",Mar!$E$2:$E$4000,">100") -> 70 | E15: =COUNTIFS(Mar!$C$2:$C$4000,"PSYSTEM_1005",Mar!$E$2:$E$4000,">100") -> 311 | F15: 72 | G15: 7
A16: 1002 - Luiz | B16: =COUNTIFS(Mar!$B$2:$B$4000,"PSYSTEM_1002",Mar!$E$2:$E$4000,">100",Mar!$L$2:$L$4000,">0") -> 14 | C16: =COUNTIFS(Mar!$C$2:$C$4000,"PSYSTEM_1002",Mar!$E$2:$E$4000,">100",Mar!$L$2:$L$4000,">0")+G16 -> 111 | D16: =COUNTIFS(Mar!$B$2:$B$4000,"PSYSTEM_1002",Mar!$E$2:$E$4000,">100") -> 48 | E16: =COUNTIFS(Mar!$C$2:$C$4000,"PSYSTEM_1002",Mar!$E$2:$E$4000,">100") -> 241 | F16: 91 | G16: 11
A17: 1004 - Lukas | B17: =COUNTIFS(Mar!$B$2:$B$4000,"PSYSTEM_1004",Mar!$E$2:$E$4000,">100",Mar!$L$2:$L$4000,">0") -> 5 | C17: =COUNTIFS(Mar!$C$2:$C$4000,"PSYSTEM_1004",Mar!$E$2:$E$4000,">100",Mar!$L$2:$L$4000,">0")+G17 -> 70 | D17: =COUNTIFS(Mar!$B$2:$B$4000,"PSYSTEM_1004",Mar!$E$2:$E$4000,">100") -> 45 | E17: =COUNTIFS(Mar!$C$2:$C$4000,"PSYSTEM_1004",Mar!$E$2:$E$4000,">100") -> 282 | F17: 78 | G17: 11
A18: 1013 - Lucas | B18: =COUNTIFS(Mar!$B$2:$B$4000,"PSYSTEM_1013",Mar!$E$2:$E$4000,">100",Mar!$L$2:$L$4000,">0") -> 5 | C18: =COUNTIFS(Mar!$C$2:$C$4000,"PSYSTEM_1013",Mar!$E$2:$E$4000,">100",Mar!$L$2:$L$4000,">0")+G18 -> 62 | D18: =COUNTIFS(Mar!$B$2:$B$4000,"PSYSTEM_1013",Mar!$E$2:$E$4000,">100") -> 37 | E18: =COUNTIFS(Mar!$C$2:$C$4000,"PSYSTEM_1013",Mar!$E$2:$E$4000,">100") -> 224 | F18: 130 | G18: 13
A19: 1001 - Gabriel | B19: =COUNTIFS(Mar!$B$2:$B$4000,"PSYSTEM_1001",Mar!$E$2:$E$4000,">100",Mar!$L$2:$L$4000,">0") -> 2 | C19: =COUNTIFS(Mar!$C$2:$C$4000,"PSYSTEM_1001",Mar!$E$2:$E$4000,">100",Mar!$L$2:$L$4000,">0")+G19 -> 76 | D19: =COUNTIFS(Mar!$B$2:$B$4000,"PSYSTEM_1001",Mar!$E$2:$E$4000,">100") -> 32 | E19: =COUNTIFS(Mar!$C$2:$C$4000,"PSYSTEM_1001",Mar!$E$2:$E$4000,">100") -> 223 | F19: 127 | G19: 19
A21: QSA = QUANTIDADE DE SAIDAS AVALIADA
A22: QEA = QUANTIDADE DE ENTRADAS AVALIADAS
A23: TS - TOTAL DE SAIDAS
A24: TE - TOTAL DE ENTRADAS

Sheet Notas Trim
A1: 1005 - Dayane | B1: 1002 - Luiz | C1: 1004 - Lukas | D1: 1013 - Lucas | E1: 1001 - Gabriel
A2: 5 | B2: 5 | C2: 5 | D2: 5 | E2: 5
A3: 3 | B3: 5 | C3: 5 | D3: 5 | E3: 5
A4: 5 | B4: 5 | C4: 5 | D4: 5 | E4: 5
A5: 5 | B5: 5 | C5: 5 | D5: 5 | E5: 5
A6: 5 | B6: 5 | C6: 5 | D6: 5 | E6: 5
A7: 5 | B7: 5 | C7: 5 | D7: 5 | E7: 5
A8: 5 | B8: 5 | C8: 5 | D8: 5 | E8: 5
A9: 5 | B9: 5 | C9: 4 | D9: 5 | E9: 4
A10: 5 | B10: 5 | C10: 5 | D10: 5 | E10: 5
A11: 5 | B11: 5 | C11: 5 | D11: 5 | E11: 5
A12: 5 | B12: 5 | C12: 5 | D12: 5 | E12: 5
A13: 5 | B13: 5 | C13: 5 | D13: 5 | E13: 5
... A178: 4 | B178: 5 | C178: 5 | D178: 5 | E178: 5
A179: 5 | B179: 5 | C179: 5 | E179: 5
A180: 5 | B180: 5 | C180: 5 | E180: 5
A181: 5 | B181: 3 | C181: 5 | E181: 5
A182: 4 | B182: 5 | C182: 5 | E182: 5
A183: 5 | B183: 4 | C183: 5 | E183: 5
A184: 5 | B184: 5 | C184: 5 | E184: 5
A185: 5 | B185: 5 | C185: 5 | E185: 5
A186: 5 | B186: 5 | C186: 5 | E186: 5
A187: 5 | B187: 5 | C187: 5 | E187: 5
A188: 5 | B188: 5 | C188: 5 | E188: 5
A189: 5 | B189: 5 | C189: 5 | E189: 5
A190: 5 | B190: 5 | C190: 5 | E190: 5
... A196: 4 | B196: 5 | C196: 5 | E196: 5
A197: 5 | B197: 5 | C197: 5
A198: 5 | B198: 4 | C198: 5
A199: 5 | B199: 5 | C199: 5
A200: 5 | B200: 5 | C200: 5
A201: 5 | B201: 5
A202: 5 | B202: 5
A203: 5 | B203: 5
A204: 5 | B204: 5
A205: 5 | B205: 5
A206: 5 | B206: 5
A207: 5 | B207: 5
A208: 5 | B208: 5
A209: 5 | B209: 5
...

Sheet NPS Trim
A1: ATENDENTE | B1: QTD ATENDIMENTOS | C1: QTD AVALIADOS | D1: PERCENTUAL AVALIAÇÃO | E1: MÉDIA NOTAS | F1: DESCONTOS AVALIAÇÕES | G1: MÉDIA NOTAS FINAL | J1: BONIFICAÇÃO
A2: 1005 - Dayane | B2: =D15+E15+F15 -> 1095 | C2: =B15+C15 -> 327 | D2: =C2/B2 -> 0.29863014 | E2: =AVERAGE('Notas Trim'!A$2:A$346) -> 4.8980263 | G2: =E2-F2 -> 4.8980263 | J2: =IF((((E15+B15+F15)*G2)/10)>500,500,((E15+B15+F15)*G2/10)) -> 469.72072
A3: 1002 - Luiz | B3: =D16+E16+F16 -> 1080 | C3: =B16+C16 -> 378 | D3: =C3/B3 -> 0.35 | E3: =AVERAGE('Notas Trim'!B$2:B$346) -> 4.9333333 | G3: =E3-F3 -> 4.9333333 | J3: =IF((((E16+B16+F16)*G3)/10)>500,500,((E16+B16+F16)*G3/10)) -> 480.50667
A4: 1004 - Lukas | B4: =D17+E17+F17 -> 1176 | C4: =B17+C17 -> 228 | D4: =C4/B4 -> 0.19387755 | E4: =AVERAGE('Notas Trim'!C$2:C$346) -> 4.959799 | G4: =E4-F4 -> 4.959799 | J4: =IF((((E17+B17+F17)*G4)/10)>500,500,((E17+B17+F17)*G4/10)) -> 500
A5: 1013 - Lucas | B5: =D18+E18+F18 -> 1142 | C5: =B18+C18 -> 220 | D5: =C5/B5 -> 0.19264448 | E5: =AVERAGE('Notas Trim'!D$2:D$346) -> 4.9378531 | G5: =E5-F5 -> 4.9378531 | J5: =IF((((E18+B18+F18)*G5)/10)>500,500,((E18+B18+F18)*G5/10)) -> 500
A6: 1001 - Gabriel | B6: =D19+E19+F19 -> 1103 | C6: =B19+C19 -> 247 | D6: =C6/B6 -> 0.22393472 | E6: =AVERAGE('Notas Trim'!E$2:E$346) -> 4.974359 | G6: =E6-F6 -> 4.974359 | J6: =IF((((E19+B19+F19)*G6)/10)>500,500,((E19+B19+F19)*G6/10)) -> 497.93333
A9: TOTAL | B9: =SUM(B2:B7) -> 5596 | C9: =SUM(C2:C7) -> 1400 | D9: =C9/B9 -> 0.2501787 | E9: =AVERAGE(E2:E7) -> 4.9406741 | G9: =E9-F9 -> 4.9406741 | J9: =SUM(J2:J7) -> 2448.1607
A14: ATENDENTE | B14: QSA | C14: QEA | D14: TS FONE | E14: TE FONE | F14: TE WHATS | G14: WHATS AVALIADOS
A15: 1005 - Dayane | B15: ='Nps Jan'!B15+'Nps Fev'!B15+'Nps Mar'!B15 -> 39 | C15: ='Nps Jan'!C15+'Nps Fev'!C15+'Nps Mar'!C15 -> 288 | D15: ='Nps Jan'!D15+'Nps Fev'!D15+'Nps Mar'!D15 -> 175 | E15: ='Nps Jan'!E15+'Nps Fev'!E15+'Nps Mar'!E15 -> 734 | F15: ='Nps Jan'!F15+'Nps Fev'!F15+'Nps Mar'!F15 -> 186 | G15: ='Nps Jan'!G15+'Nps Fev'!G15+'Nps Mar'!G15 -> 23
A16: 1002 - Luiz | B16: ='Nps Jan'!B16+'Nps Fev'!B16+'Nps Mar'!B16 -> 42 | C16: ='Nps Jan'!C16+'Nps Fev'!C16+'Nps Mar'!C16 -> 336 | D16: ='Nps Jan'!D16+'Nps Fev'!D16+'Nps Mar'!D16 -> 148 | E16: ='Nps Jan'!E16+'Nps Fev'!E16+'Nps Mar'!E16 -> 693 | F16: ='Nps Jan'!F16+'Nps Fev'!F16+'Nps Mar'!F16 -> 239 | G16: ='Nps Jan'!G16+'Nps Fev'!G16+'Nps Mar'!G16 -> 31
A17: 1004 - Lukas | B17: ='Nps Jan'!B17+'Nps Fev'!B17+'Nps Mar'!B17 -> 13 | C17: ='Nps Jan'!C17+'Nps Fev'!C17+'Nps Mar'!C17 -> 215 | D17: ='Nps Jan'!D17+'Nps Fev'!D17+'Nps Mar'!D17 -> 117 | E17: ='Nps Jan'!E17+'Nps Fev'!E17+'Nps Mar'!E17 -> 825 | F17: ='Nps Jan'!F17+'Nps Fev'!F17+'Nps Mar'!F17 -> 234 | G17: ='Nps Jan'!G17+'Nps Fev'!G17+'Nps Mar'!G17 -> 29
A18: 1013 - Lucas | B18: ='Nps Jan'!B18+'Nps Fev'!B18+'Nps Mar'!B18 -> 21 | C18: ='Nps Jan'!C18+'Nps Fev'!C18+'Nps Mar'!C18 -> 199 | D18: ='Nps Jan'!D18+'Nps Fev'!D18+'Nps Mar'!D18 -> 123 | E18: ='Nps Jan'!E18+'Nps Fev'!E18+'Nps Mar'!E18 -> 686 | F18: ='Nps Jan'!F18+'Nps Fev'!F18+'Nps Mar'!F18 -> 333 | G18: ='Nps Jan'!G18+'Nps Fev'!G18+'Nps Mar'!G18 -> 43
A19: 1001 - Gabriel | B19: ='Nps Jan'!B19+'Nps Fev'!B19+'Nps Mar'!B19 -> 14 | C19: ='Nps Jan'!C19+'Nps Fev'!C19+'Nps Mar'!C19 -> 233 | D19: ='Nps Jan'!D19+'Nps Fev'!D19+'Nps Mar'!D19 -> 116 | E19: ='Nps Jan'!E19+'Nps Fev'!E19+'Nps Mar'!E19 -> 648 | F19: ='Nps Jan'!F19+'Nps Fev'!F19+'Nps Mar'!F19 -> 339 | G19: ='Nps Jan'!G19+'Nps Fev'!G19+'Nps Mar'!G19 -> 52
A21: QSA = QUANTIDADE DE SAIDAS AVALIADA
A22: QEA = QUANTIDADE DE ENTRADAS AVALIADAS
A23: TS - TOTAL DE SAIDAS
A24: TE - TOTAL DE ENTRADAS
