Workbook

Sheet Abr
A1: date | B1: src | C1: dst | D1: did | E1: duration | F1: talk | G1: status | H1: uniqueid | I1: direction | J1: coust_center | K1: queue_name | L1: nps
A2: 46142.74 | B2: PSYSTEM_1008 | C2: 11963903641 | E2: 5 | F2: 0 | G2: UNKNOWN | H2: FlexPBX-1777581957.242579 | I2: S | J2: COMERCIAL - POWER SYSTEM
A3: 46142.739 | B3: PSYSTEM_1008 | C3: 92982774522 | E3: 12 | F3: 2 | G3: ANSWERED | H3: FlexPBX-1777581855.242565 | I3: S | J3: COMERCIAL - POWER SYSTEM
A4: 46142.737 | B4: PSYSTEM_1008 | C4: 37999995076 | E4: 12 | F4: 3 | G4: ANSWERED | H4: FlexPBX-1777581679.242551 | I4: S | J4: COMERCIAL - POWER SYSTEM
A5: 46142.736 | B5: PSYSTEM_1008 | C5: 24992577455 | E5: 28 | F5: 6 | G5: ANSWERED | H5: FlexPBX-1777581575.242537 | I5: S | J5: COMERCIAL - POWER SYSTEM
A6: 46142.734 | B6: PSYSTEM_1008 | C6: 28999457117 | E6: 8 | F6: 0 | G6: UNKNOWN | H6: FlexPBX-1777581423.242529 | I6: S | J6: COMERCIAL - POWER SYSTEM
A7: 46142.733 | B7: PSYSTEM_1008 | C7: 11999610017 | E7: 3 | F7: 0 | G7: UNKNOWN | H7: FlexPBX-1777581357.242521 | I7: S | J7: COMERCIAL - POWER SYSTEM
A8: 46142.732 | B8: 4421032936 | C8: 4430265054 | D8: 4430265054 | E8: 3 | F8: 2 | G8: NO ANSWER | H8: FlexPBX-1777581215.242516 | I8: E | J8: GERAL - POWER SYSTEM
A9: 46142.71 | B9: PSYSTEM_1000 | C9: 4436292220 | E9: 392 | F9: 375 | G9: ANSWERED | H9: FlexPBX-1777579336.242496 | I9: S | J9: SUPORTE - POWER SYSTEM
A10: 46142.707 | B10: 44998636008 | C10: PSYSTEM_1005 | D10: 4430265054 | E10: 649 | F10: 599 | G10: ANSWERED | H10: FlexPBX-1777579112.242452 | I10: E | J10: SUPORTE - POWER SYSTEM | K10: PSYSTEM_SUPORTE | L10: 5
A11: 46142.7 | B11: 1143744993 | C11: PSYSTEM_1013 | D11: 4431268225 | E11: 810 | F11: 729 | G11: ANSWERED | H11: FlexPBX-1777578485.242395 | I11: E | J11: SUPORTE - POWER SYSTEM | K11: PSYSTEM_SUPORTE
A12: 46142.691 | B12: 3432424736 | C12: PSYSTEM_1002 | D12: 4430265054 | E12: 232 | F12: 194 | G12: ANSWERED | H12: FlexPBX-1777577685.242362 | I12: E | J12: SUPORTE - POWER SYSTEM | K12: PSYSTEM_SUPORTE
A13: 46142.688 | B13: PSYSTEM_1004 | C13: 6434530674 | E13: 400 | F13: 394 | G13: ANSWERED | H13: FlexPBX-1777577445.242354 | I13: S | J13: SUPORTE - POWER SYSTEM
A14: 46142.682 | B14: 4421032924 | C14: 4430265054 | D14: 4430265054 | E14: 3 | F14: 2 | G14: NO ANSWER | H14: FlexPBX-1777576902.242349 | I14: E | J14: GERAL - POWER SYSTEM
A15: 46142.676 | B15: 4435226025 | C15: PSYSTEM_1004 | D15: 4430265054 | E15: 196 | F15: 157 | G15: ANSWERED | H15: FlexPBX-1777576390.242319 | I15: E | J15: SUPORTE - POWER SYSTEM | K15: PSYSTEM_SUPORTE
A16: 46142.67 | B16: PSYSTEM_1002 | C16: 3432424736 | E16: 159 | F16: 158 | G16: ANSWERED | H16: FlexPBX-1777575918.242290 | I16: S | J16: SUPORTE - POWER SYSTEM
A17: 46142.67 | B17: 4430346845 | C17: PSYSTEM_1004 | D17: 4430265054 | E17: 112 | F17: 76 | G17: ANSWERED | H17: FlexPBX-1777575903.242287 | I17: E | J17: SUPORTE - POWER SYSTEM | K17: PSYSTEM_SUPORTE
A18: 46142.67 | B18: 4133491428 | C18: PSYSTEM_1005 | D18: 4430265054 | E18: 616 | F18: 580 | G18: ANSWERED | H18: FlexPBX-1777575846.242248 | I18: E | J18: SUPORTE - POWER SYSTEM | K18: PSYSTEM_SUPORTE
A19: 46142.656 | B19: PSYSTEM_1006 | C19: 4436295470 | E19: 267 | F19: 260 | G19: ANSWERED | H19: FlexPBX-1777574719.242208 | I19: S | J19: COMERCIAL - POWER SYSTEM
A20: 46142.656 | B20: PSYSTEM_1006 | C20: 4436295470 | E20: 7 | F20: 6 | G20: ANSWERED | H20: FlexPBX-1777574709.242194 | I20: S | J20: COMERCIAL - POWER SYSTEM
A21: 46142.656 | B21: PSYSTEM_1013 | C21: 4430152533 | E21: 110 | F21: 86 | G21: ANSWERED | H21: FlexPBX-1777574649.242176 | I21: S | J21: SUPORTE - POWER SYSTEM
A22: 46142.656 | B22: PSYSTEM_1013 | C22: 4430152533 | E22: 26 | F22: 25 | G22: ANSWERED | H22: FlexPBX-1777574643.242164 | I22: S | J22: SUPORTE - POWER SYSTEM
A23: 46142.655 | B23: PSYSTEM_1006 | C23: 44999688098 | E23: 1 | F23: 0 | G23: UNKNOWN | H23: FlexPBX-1777574630.242156 | I23: S | J23: COMERCIAL - POWER SYSTEM
A24: 46142.655 | B24: PSYSTEM_1006 | C24: 44999688098 | E24: 1 | F24: 0 | G24: UNKNOWN | H24: FlexPBX-1777574594.242148 | I24: S | J24: COMERCIAL - POWER SYSTEM
A25: 46142.653 | B25: PSYSTEM_1008 | C25: 11996276137 | E25: 57 | F25: 43 | G25: ANSWERED | H25: FlexPBX-1777574406.242134 | I25: S | J25: COMERCIAL - POWER SYSTEM
A26: 46142.651 | B26: PSYSTEM_1013 | C26: 91981481202 | E26: 44 | F26: 39 | G26: ANSWERED | H26: FlexPBX-1777574213.242118 | I26: S | J26: SUPORTE - POWER SYSTEM
A27: 46142.649 | B27: PSYSTEM_1005 | C27: 45999334612 | E27: 43 | F27: 29 | G27: ANSWERED | H27: FlexPBX-1777574091.242092 | I27: S | J27: SUPORTE - POWER SYSTEM
A28: 46142.649 | B28: PSYSTEM_1008 | C28: 51998609261 | E28: 10 | F28: 0 | G28: UNKNOWN | H28: FlexPBX-1777574040.242084 | I28: S | J28: COMERCIAL - POWER SYSTEM
A29: 46142.647 | B29: 44999670264 | C29: PSYSTEM_1002 | D29: 4430265054 | E29: 290 | F29: 266 | G29: ANSWERED | H29: FlexPBX-1777573923.242063 | I29: E | J29: SUPORTE - POWER SYSTEM | K29: PSYSTEM_SUPORTE | L29: 5
A30: 46142.642 | B30: 45999334612 | C30: PSYSTEM_1005 | D30: 4430265054 | E30: 469 | F30: 449 | G30: ANSWERED | H30: FlexPBX-1777573454.242036 | I30: E | J30: SUPORTE - POWER SYSTEM | K30: PSYSTEM_SUPORTE | L30: 5
A31: 46142.64 | B31: 91981481202 | C31: PSYSTEM_1013 | D31: 4430265054 | E31: 842 | F31: 817 | G31: ANSWERED | H31: FlexPBX-1777573277.241997 | I31: E | J31: SUPORTE - POWER SYSTEM | K31: PSYSTEM_SUPORTE
A32: 46142.62 | B32: 67992169496 | C32: PSYSTEM_1005 | D32: 4430265054 | E32: 220 | F32: 176 | G32: ANSWERED | H32: FlexPBX-1777571546.241958 | I32: E | J32: SUPORTE - POWER SYSTEM | K32: PSYSTEM_SUPORTE
A33: 46142.611 | B33: 44998721566 | C33: PSYSTEM_1002 | D33: 4430265054 | E33: 1197 | F33: 1146 | G33: ANSWERED | H33: FlexPBX-1777570759.241914 | I33: E | J33: SUPORTE - POWER SYSTEM | K33: PSYSTEM_SUPORTE
A34: 46142.609 | B34: 3130691100 | C34: 4531273156 | D34: 4531273156 | E34: 47 | F34: 46 | G34: NO ANSWER | H34: FlexPBX-1777570637.241889 | I34: E | J34: GERAL - POWER SYSTEM | K34: PSYSTEM_SUPORTE
A35: 46142.607 | B35: 44999859732 | C35: PSYSTEM_1005 | D35: 4430265054 | E35: 293 | F35: 225 | G35: ANSWERED | H35: FlexPBX-1777570448.241834 | I35: E | J35: SUPORTE - POWER SYSTEM | K35: PSYSTEM_SUPORTE | L35: 5
A36: 46142.603 | B36: 4433015977 | C36: 4430265054 | D36: 4430265054 | E36: 3 | F36: 2 | G36: NO ANSWER | H36: FlexPBX-1777570125.241823 | I36: E | J36: GERAL - POWER SYSTEM
A37: 46142.594 | B37: 11990144272 | C37: PSYSTEM_1004 | D37: 4431268225 | E37: 1067 | F37: 979 | G37: ANSWERED | H37: FlexPBX-1777569317.241751 | I37: E | J37: SUPORTE - POWER SYSTEM | K37: PSYSTEM_SUPORTE | L37: 5
A38: 46142.59 | B38: PSYSTEM_1005 | C38: 4430289556 | E38: 198 | F38: 186 | G38: ANSWERED | H38: FlexPBX-1777568985.241735 | I38: S | J38: SUPORTE - POWER SYSTEM | L38: 5
A39: 46142.59 | B39: PSYSTEM_1005 | C39: 4430289556 | E39: 26 | F39: 25 | G39: ANSWERED | H39: FlexPBX-1777568977.241723 | I39: S | J39: SUPORTE - POWER SYSTEM
A40: 46142.584 | B40: 43984810043 | C40: PSYSTEM_1002 | D40: 4430265054 | E40: 1121 | F40: 1060 | G40: ANSWERED | H40: FlexPBX-1777568476.241686 | I40: E | J40: SUPORTE - POWER SYSTEM | K40: PSYSTEM_SUPORTE
...

Sheet Notas Abr
A1: 1005 - Dayane | B1: 1002 - Luiz | C1: 1004 - Lukas | D1: 1013 - Lucas | E1: 1003 - Pamela
A2: 5 | B2: 5 | C2: 5 | D2: 5 | E2: 5
A3: 5 | B3: 5 | C3: 5 | D3: 5 | E3: 5
A4: 5 | B4: 5 | C4: 5 | D4: 5 | E4: 5
A5: 5 | B5: 5 | C5: 5 | D5: 5 | E5: 5
A6: 5 | B6: 5 | C6: 5 | D6: 5 | E6: 5
A7: 5 | B7: 5 | C7: 5 | D7: 5 | E7: 5
A8: 5 | B8: 5 | C8: 5 | D8: 5 | E8: 5
A9: 5 | B9: 5 | C9: 5 | D9: 5 | E9: 5
A10: 5 | B10: 5 | C10: 5 | D10: 5 | E10: 5
A11: 5 | B11: 5 | C11: 4 | D11: 5 | E11: 5
A12: 5 | B12: 5 | C12: 5 | D12: 5 | E12: 5
A13: 5 | B13: 5 | C13: 5 | D13: 5
A14: 5 | B14: 5 | C14: 5 | D14: 5
A15: 5 | B15: 5 | C15: 5 | D15: 5
A16: 5 | B16: 5 | C16: 5 | D16: 5
A17: 5 | B17: 5 | C17: 5 | D17: 5
A18: 5 | B18: 5 | C18: 5 | D18: 5
A19: 5 | B19: 5 | C19: 5 | D19: 5
A20: 5 | B20: 5 | C20: 5 | D20: 4
A21: 5 | B21: 5 | C21: 5 | D21: 5
A22: 5 | B22: 5 | C22: 5 | D22: 5
A23: 5 | B23: 5 | C23: 5 | D23: 5
A24: 5 | B24: 5 | C24: 5 | D24: 5
... A71: 5 | B71: 5 | C71: 4 | D71: 4
A72: 5 | B72: 5 | C72: 5
A73: 5 | B73: 5 | C73: 5
A74: 5 | B74: 5 | C74: 5
A75: 5 | B75: 5 | C75: 5
A76: 5 | B76: 5 | C76: 5
A77: 5 | B77: 5 | C77: 5
A78: 5 | B78: 5 | C78: 5
A79: 5 | B79: 5 | C79: 5
A80: 5 | B80: 4 | C80: 5
A81: 5 | B81: 5 | C81: 5
A82: 5 | B82: 5 | C82: 5
A83: 5 | B83: 5 | C83: 5
... A109: 5 | B109: 5 | C109: 5
B110: 5 | C110: 5
B111: 5
...

Sheet Nps Abr
A1: ATENDENTE | B1: QTD ATENDIMENTOS | C1: QTD AVALIADOS | D1: PERCENTUAL AVALIAÇÃO | E1: MÉDIA NOTAS | F1: DESCONTOS AVALIAÇÕES | G1: MÉDIA NOTAS FINAL | I1: PONTUAÇÃO CAIXINHA
A2: 1005 - Dayane | B2: =D15+E15+F15 -> 374 | C2: =B15+C15 -> 108 | D2: =C2/B2 -> 0.28877005 | E2: =AVERAGE('Notas Abr'!$A$2:$A$200) -> 4.9907407 | G2: =E2-F2 -> 4.9907407 | I2: =G2*C2 -> 539
A3: 1002 - Luiz | B3: =D16+E16+F16 -> 348 | C3: =B16+C16 -> 115 | D3: =C3/B3 -> 0.33045977 | E3: =AVERAGE('Notas Abr'!$B$2:$B$200) -> 4.9652174 | G3: =E3-F3 -> 4.9652174 | I3: =G3*C3 -> 571
A4: 1004 - Lukas | B4: =D17+E17+F17 -> 346 | C4: =B17+C17 -> 109 | D4: =C4/B4 -> 0.3150289 | E4: =AVERAGE('Notas Abr'!$C$2:$C$200) -> 4.9541284 | G4: =E4-F4 -> 4.9541284 | I4: =G4*C4 -> 540
A5: 1013 - Lucas | B5: =D18+E18+F18 -> 317 | C5: =B18+C18 -> 70 | D5: =C5/B5 -> 0.22082019 | E5: =AVERAGE('Notas Abr'!$D$2:$D$200) -> 4.9642857 | G5: =E5-F5 -> 4.9642857 | I5: =G5*C5 -> 347.5
A6: 1003 - Pamela | B6: =D19+E19+F19 -> 34 | C6: =B19+C19 -> 11 | D6: =C6/B6 -> 0.32352941 | E6: =AVERAGE('Notas Abr'!$E$2:$E$200) -> 5 | G6: =E6-F6 -> 5 | I6: =G6*C6 -> 55
A9: TOTAL | B9: =SUM(B2:B7) -> 1419 | C9: =SUM(C2:C7) -> 413 | D9: =C9/B9 -> 0.29105004 | E9: =AVERAGE(E2:E7) -> 4.9748745 | G9: =E9-F9 -> 4.9748745
A14: ATENDENTE | B14: QSA | C14: QEA | D14: TS FONE | E14: TE FONE | F14: TE WHATS | G14: WHATS AVALIADOS
A15: 1005 - Dayane | B15: =COUNTIFS(Abr!$B$2:$B$3000,"PSYSTEM_1005",Abr!$E$2:$E$3000,">100",Abr!$L$2:$L$3000,">0") -> 17 | C15: =COUNTIFS(Abr!$C$2:$C$4000,"PSYSTEM_1005",Abr!$E$2:$E$4000,">100",Abr!$L$2:$L$4000,">0")+G15 -> 91 | D15: =COUNTIFS(Abr!$B$2:$B$4000,"PSYSTEM_1005",Abr!$E$2:$E$4000,">100") -> 66 | E15: =COUNTIFS(Abr!$C$2:$C$4000,"PSYSTEM_1005",Abr!$E$2:$E$4000,">100") -> 236 | F15: 72 | G15: 9
A16: 1002 - Luiz | B16: =COUNTIFS(Abr!$B$2:$B$3000,"PSYSTEM_1002",Abr!$E$2:$E$3000,">100",Abr!$L$2:$L$3000,">0") -> 9 | C16: =COUNTIFS(Abr!$C$2:$C$4000,"PSYSTEM_1002",Abr!$E$2:$E$4000,">100",Abr!$L$2:$L$4000,">0")+G16 -> 106 | D16: =COUNTIFS(Abr!$B$2:$B$4000,"PSYSTEM_1002",Abr!$E$2:$E$4000,">100") -> 53 | E16: =COUNTIFS(Abr!$C$2:$C$4000,"PSYSTEM_1002",Abr!$E$2:$E$4000,">100") -> 198 | F16: 97 | G16: 17
A17: 1004 - Lukas | B17: =COUNTIFS(Abr!$B$2:$B$3000,"PSYSTEM_1004",Abr!$E$2:$E$3000,">100",Abr!$L$2:$L$3000,">0") -> 10 | C17: =COUNTIFS(Abr!$C$2:$C$4000,"PSYSTEM_1004",Abr!$E$2:$E$4000,">100",Abr!$L$2:$L$4000,">0")+G17 -> 99 | D17: =COUNTIFS(Abr!$B$2:$B$4000,"PSYSTEM_1004",Abr!$E$2:$E$4000,">100") -> 44 | E17: =COUNTIFS(Abr!$C$2:$C$4000,"PSYSTEM_1004",Abr!$E$2:$E$4000,">100") -> 229 | F17: 73 | G17: 17
A18: 1013 - Lucas | B18: =COUNTIFS(Abr!$B$2:$B$3000,"PSYSTEM_1013",Abr!$E$2:$E$3000,">100",Abr!$L$2:$L$3000,">0") -> 2 | C18: =COUNTIFS(Abr!$C$2:$C$4000,"PSYSTEM_1013",Abr!$E$2:$E$4000,">100",Abr!$L$2:$L$4000,">0")+G18 -> 68 | D18: =COUNTIFS(Abr!$B$2:$B$4000,"PSYSTEM_1013",Abr!$E$2:$E$4000,">100") -> 18 | E18: =COUNTIFS(Abr!$C$2:$C$4000,"PSYSTEM_1013",Abr!$E$2:$E$4000,">100") -> 167 | F18: 132 | G18: 20
A19: 1003 - Pamela | B19: =COUNTIFS(Abr!$B$2:$B$3000,"PSYSTEM_1003",Abr!$E$2:$E$3000,">100",Abr!$L$2:$L$3000,">0") -> 0 | C19: =COUNTIFS(Abr!$C$2:$C$4000,"PSYSTEM_1003",Abr!$E$2:$E$4000,">100",Abr!$L$2:$L$4000,">0")+G19 -> 11 | D19: =COUNTIFS(Abr!$B$2:$B$4000,"PSYSTEM_1003",Abr!$E$2:$E$4000,">100") -> 0 | E19: =COUNTIFS(Abr!$C$2:$C$4000,"PSYSTEM_1003",Abr!$E$2:$E$4000,">100") -> 0 | F19: 34 | G19: 11
A21: QSA = QUANTIDADE DE SAIDAS AVALIADA
A22: QEA = QUANTIDADE DE ENTRADAS AVALIADAS
A23: TS - TOTAL DE SAIDAS
A24: TE - TOTAL DE ENTRADAS

Sheet Mai
A1: date | B1: src | C1: dst | D1: did | E1: duration | F1: talk | G1: status | H1: uniqueid | I1: direction | J1: coust_center | K1: queue_name | L1: nps
A2: 46172.511 | B2: 44997134514 | C2: 4430265054 | D2: 4430265054 | E2: 19 | F2: 18 | G2: NO ANSWER | H2: FlexPBX-1780154142.308536 | I2: E | J2: GERAL - POWER SYSTEM
A3: 46172.381 | B3: 1438160351 | C3: 4430265054 | D3: 4430265054 | E3: 9 | F3: 8 | G3: NO ANSWER | H3: FlexPBX-1780142920.308531 | I3: E | J3: GERAL - POWER SYSTEM
A4: 46171.743 | B4: 44988067937 | C4: PSYSTEM_1002 | D4: 4430265054 | E4: 410 | F4: 370 | G4: ANSWERED | H4: FlexPBX-1780087753.308477 | I4: E | J4: SUPORTE - POWER SYSTEM | K4: PSYSTEM_SUPORTE
A5: 46171.731 | B5: 44997426611 | C5: PSYSTEM_1000 | D5: 4430265054 | E5: 333 | F5: 332 | G5: ANSWERED | H5: FlexPBX-1780086763.308401 | I5: E | J5: SUPORTE - POWER SYSTEM | K5: PSYSTEM_SUPORTE
A6: 46171.72 | B6: 44988255390 | C6: PSYSTEM_1004 | D6: 4430265054 | E6: 714 | F6: 578 | G6: ANSWERED | H6: FlexPBX-1780085780.308295 | I6: E | J6: SUPORTE - POWER SYSTEM | K6: PSYSTEM_SUPORTE
A7: 46171.707 | B7: 4430315826 | C7: 4430265054 | D7: 4430265054 | E7: 45 | F7: 45 | G7: NO ANSWER | H7: FlexPBX-1780084645.308260 | I7: E | J7: GERAL - POWER SYSTEM | K7: PSYSTEM_SUPORTE
A8: 46171.7 | B8: 44999647912 | C8: PSYSTEM_1002 | D8: 4430265054 | E8: 1213 | F8: 1190 | G8: ANSWERED | H8: FlexPBX-1780084107.308240 | I8: E | J8: SUPORTE - POWER SYSTEM | K8: PSYSTEM_SUPORTE
A9: 46171.688 | B9: 44999647912 | C9: PSYSTEM_1005 | D9: 4430265054 | E9: 295 | F9: 247 | G9: ANSWERED | H9: FlexPBX-1780083002.308198 | I9: E | J9: SUPORTE - POWER SYSTEM | K9: PSYSTEM_SUPORTE
A10: 46171.686 | B10: 4430317020 | C10: 4430265054 | D10: 4430265054 | E10: 84 | F10: 83 | G10: NO ANSWER | H10: FlexPBX-1780082886.308129 | I10: E | J10: GERAL - POWER SYSTEM | K10: PSYSTEM_SUPORTE
A11: 46171.681 | B11: 1123291051 | C11: PSYSTEM_1013 | D11: 4430265054 | E11: 192 | F11: 155 | G11: ANSWERED | H11: FlexPBX-1780082429.308087 | I11: E | J11: SUPORTE - POWER SYSTEM | K11: PSYSTEM_SUPORTE
A12: 46171.681 | B12: 44937753453 | C12: 4430265054 | D12: 4430265054 | E12: 6 | F12: 5 | G12: NO ANSWER | H12: FlexPBX-1780082400.308078 | I12: E | J12: GERAL - POWER SYSTEM
A13: 46171.676 | B13: 1144273633 | C13: 4430265054 | D13: 4430265054 | E13: 10 | F13: 10 | G13: NO ANSWER | H13: FlexPBX-1780082043.308073 | I13: E | J13: GERAL - POWER SYSTEM
A14: 46171.676 | B14: 4430317020 | C14: PSYSTEM_1002 | D14: 4430265054 | E14: 649 | F14: 609 | G14: ANSWERED | H14: FlexPBX-1780081976.308045 | I14: E | J14: SUPORTE - POWER SYSTEM | K14: PSYSTEM_SUPORTE | L14: 5
A15: 46171.672 | B15: 44999827582 | C15: PSYSTEM_1005 | D15: 4430265054 | E15: 815 | F15: 705 | G15: ANSWERED | H15: FlexPBX-1780081640.307947 | I15: E | J15: SUPORTE - POWER SYSTEM | K15: PSYSTEM_SUPORTE | L15: 5
A16: 46171.63 | B16: PSYSTEM_1005 | C16: 44991395073 | E16: 850 | F16: 839 | G16: ANSWERED | H16: FlexPBX-1780078028.307921 | I16: S | J16: SUPORTE - POWER SYSTEM | L16: 5
A17: 46171.63 | B17: PSYSTEM_1005 | C17: 44991395073 | E17: 5 | F17: 0 | G17: UNKNOWN | H17: FlexPBX-1780078012.307913 | I17: S | J17: SUPORTE - POWER SYSTEM
A18: 46171.624 | B18: 6234347959 | C18: PSYSTEM_1004 | D18: 4430265054 | E18: 1259 | F18: 1232 | G18: ANSWERED | H18: FlexPBX-1780077552.307883 | I18: E | J18: SUPORTE - POWER SYSTEM | K18: PSYSTEM_SUPORTE | L18: 5
A19: 46171.599 | B19: PSYSTEM_1002 | C19: 44991354005 | E19: 123 | F19: 116 | G19: ANSWERED | H19: FlexPBX-1780075334.307835 | I19: S | J19: SUPORTE - POWER SYSTEM
A20: 46171.598 | B20: PSYSTEM_1002 | C20: 4433321380 | E20: 5 | F20: 0 | G20: UNKNOWN | H20: FlexPBX-1780075232.307827 | I20: S | J20: SUPORTE - POWER SYSTEM
A21: 46171.593 | B21: 44991395073 | C21: PSYSTEM_1005 | D21: 4430265054 | E21: 2805 | F21: 2786 | G21: ANSWERED | H21: FlexPBX-1780074813.307799 | I21: E | J21: SUPORTE - POWER SYSTEM | K21: PSYSTEM_SUPORTE | L21: 5
A22: 46171.587 | B22: PSYSTEM_1005 | C22: 6436221416 | E22: 51 | F22: 19 | G22: ANSWERED | H22: FlexPBX-1780074356.307785 | I22: S | J22: SUPORTE - POWER SYSTEM
A23: 46171.582 | B23: PSYSTEM_1002 | C23: 44999657967 | E23: 314 | F23: 294 | G23: ANSWERED | H23: FlexPBX-1780073888.307765 | I23: S | J23: SUPORTE - POWER SYSTEM
A24: 46171.577 | B24: 43998036566 | C24: PSYSTEM_1004 | D24: 4430265054 | E24: 635 | F24: 583 | G24: ANSWERED | H24: FlexPBX-1780073485.307709 | I24: E | J24: SUPORTE - POWER SYSTEM | K24: PSYSTEM_SUPORTE | L24: 5
A25: 46171.576 | B25: PSYSTEM_1005 | C25: 6436221416 | E25: 59 | F25: 42 | G25: ANSWERED | H25: FlexPBX-1780073343.307683 | I25: S | J25: SUPORTE - POWER SYSTEM
A26: 46171.571 | B26: 44988067937 | C26: PSYSTEM_1013 | D26: 4430265054 | E26: 539 | F26: 424 | G26: ANSWERED | H26: FlexPBX-1780072935.307597 | I26: E | J26: SUPORTE - POWER SYSTEM | K26: PSYSTEM_SUPORTE
A27: 46171.565 | B27: 93991495484 | C27: PSYSTEM_1002 | D27: 4430265054 | E27: 638 | F27: 599 | G27: ANSWERED | H27: FlexPBX-1780072385.307553 | I27: E | J27: SUPORTE - POWER SYSTEM | K27: PSYSTEM_SUPORTE | L27: 5
A28: 46171.499 | B28: 1438780460 | C28: 4430265054 | D28: 4430265054 | E28: 47 | F28: 46 | G28: NO ANSWER | H28: FlexPBX-1780066674.307532 | I28: E | J28: GERAL - POWER SYSTEM | K28: PSYSTEM_SUPORTE
A29: 46171.495 | B29: 44999240941 | C29: 4430265054 | D29: 4430265054 | E29: 5 | F29: 5 | G29: NO ANSWER | H29: FlexPBX-1780066353.307527 | I29: E | J29: GERAL - POWER SYSTEM
A30: 46171.493 | B30: 93991495484 | C30: 4430265054 | D30: 4430265054 | E30: 48 | F30: 48 | G30: NO ANSWER | H30: FlexPBX-1780066155.307489 | I30: E | J30: GERAL - POWER SYSTEM | K30: PSYSTEM_SUPORTE
A31: 46171.49 | B31: 93991495484 | C31: 4430265054 | D31: 4430265054 | E31: 85 | F31: 84 | G31: NO ANSWER | H31: FlexPBX-1780065953.307436 | I31: E | J31: GERAL - POWER SYSTEM | K31: PSYSTEM_SUPORTE
A32: 46171.484 | B32: PSYSTEM_1002 | C32: 44999657967 | E32: 34 | F32: 28 | G32: ANSWERED | H32: FlexPBX-1780065403.307402 | I32: S | J32: SUPORTE - POWER SYSTEM
A33: 46171.483 | B33: PSYSTEM_1009 | C33: PSYSTEM_1006 | E33: 90 | F33: 81 | G33: ANSWERED | H33: FlexPBX-1780065327.307394 | I33: R | J33: COMERCIAL - POWER SYSTEM
A34: 46171.471 | B34: PSYSTEM_1005 | C34: 4330333542 | E34: 112 | F34: 99 | G34: ANSWERED | H34: FlexPBX-1780064273.307346 | I34: S | J34: SUPORTE - POWER SYSTEM
A35: 46171.47 | B35: PSYSTEM_1006 | C35: PSYSTEM_1009 | E35: 331 | F35: 330 | G35: ANSWERED | H35: FlexPBX-1780064231.307338 | I35: R | J35: COMERCIAL - POWER SYSTEM
A36: 46171.47 | B36: PSYSTEM_1006 | C36: PSYSTEM_1009 | E36: 9 | F36: 7 | G36: ANSWERED | H36: FlexPBX-1780064207.307324 | I36: R | J36: COMERCIAL - POWER SYSTEM
A37: 46171.469 | B37: PSYSTEM_1009 | C37: PSYSTEM_1006 | E37: 51 | F37: 43 | G37: ANSWERED | H37: FlexPBX-1780064151.307310 | I37: R | J37: COMERCIAL - POWER SYSTEM
A38: 46171.469 | B38: PSYSTEM_1006 | C38: PSYSTEM_1009 | E38: 30 | F38: 24 | G38: ANSWERED | H38: FlexPBX-1780064113.307290 | I38: R | J38: COMERCIAL - POWER SYSTEM
A39: 46171.466 | B39: 44999670264 | C39: PSYSTEM_1005 | D39: 4430265054 | E39: 307 | F39: 235 | G39: ANSWERED | H39: FlexPBX-1780063837.307189 | I39: E | J39: SUPORTE - POWER SYSTEM | K39: PSYSTEM_SUPORTE | L39: 5
A40: 46171.466 | B40: 44997687156 | C40: PSYSTEM_1004 | D40: 4430265054 | E40: 569 | F40: 452 | G40: ANSWERED | H40: FlexPBX-1780063831.307186 | I40: E | J40: SUPORTE - POWER SYSTEM | K40: PSYSTEM_SUPORTE
...

Sheet Notas Mai
A1: 1005 - Dayane | B1: 1002 - Luiz | C1: 1004 - Lukas | D1: 1013 - Lucas | E1: 1003 - Pamela
A2: 5 | B2: 5 | C2: 5 | D2: 5 | E2: 4.5
A3: 5 | B3: 5 | C3: 5 | D3: 5 | E3: 4.5
A4: 5 | B4: 5 | C4: 5 | D4: 5 | E4: 4.5
A5: 5 | B5: 4 | C5: 5 | D5: 5 | E5: 4.5
A6: 5 | B6: 5 | C6: 5 | D6: 5 | E6: 4.5
A7: 5 | B7: 5 | C7: 5 | D7: 5 | E7: 5
A8: 5 | B8: 5 | C8: 5 | D8: 5 | E8: 5
A9: 5 | B9: 5 | C9: 5 | D9: 5 | E9: 5
A10: 5 | B10: 5 | C10: 5 | D10: 5 | E10: 5
A11: 5 | B11: 5 | C11: 5 | D11: 5 | E11: 5
A12: 5 | B12: 5 | C12: 5 | D12: 5 | E12: 5
A13: 5 | B13: 5 | C13: 5 | D13: 5 | E13: 5
... A45: 5 | B45: 5 | C45: 5 | D45: 5 | E45: 5
A46: 5 | B46: 5 | C46: 5 | D46: 5
A47: 5 | B47: 5 | C47: 5 | D47: 5
A48: 5 | B48: 5 | C48: 5 | D48: 5
A49: 5 | B49: 5 | C49: 5 | D49: 5
A50: 5 | B50: 5 | C50: 5 | D50: 5
A51: 5 | B51: 5 | C51: 5 | D51: 5
A52: 5 | B52: 5 | C52: 5 | D52: 5
A53: 5 | B53: 5 | C53: 5 | D53: 5
A54: 5 | B54: 5 | C54: 5 | D54: 5
A55: 5 | B55: 5 | C55: 5 | D55: 5
A56: 5 | B56: 5 | C56: 5 | D56: 5
A57: 5 | B57: 5 | C57: 5 | D57: 5
A58: 5 | B58: 5 | C58: 5 | D58: 5
A59: 5 | C59: 5 | D59: 4
A60: 5 | C60: 4 | D60: 5
A61: 5 | C61: 5 | D61: 5
A62: 5 | C62: 5 | D62: 5
A63: 5 | C63: 5 | D63: 5
A64: 5 | C64: 5 | D64: 5
A65: 5 | C65: 5 | D65: 5
A66: 5 | C66: 5 | D66: 5
A67: 5 | C67: 5 | D67: 5
A68: 5 | C68: 5 | D68: 5
A69: 5 | C69: 5 | D69: 5
A70: 5 | C70: 5 | D70: 5
... A90: 5 | C90: 5 | D90: 4.5
...

Sheet Nps Mai
A1: ATENDENTE | B1: QTD ATENDIMENTOS | C1: QTD AVALIADOS | D1: PERCENTUAL AVALIAÇÃO | E1: MÉDIA NOTAS | F1: DESCONTOS AVALIAÇÕES | G1: MÉDIA NOTAS FINAL | I1: PONTUAÇÃO CAIXINHA
A2: 1005 - Dayane | B2: =D15+E15+F15 -> 384 | C2: =B15+C15 -> 136 | D2: =C2/B2 -> 0.35416667 | E2: =AVERAGE('Notas Mai'!$A$2:$A$72) -> 4.9577465 | G2: =E2-F2 -> 4.9577465 | I2: =G2*C2 -> 674.25352
A3: 1002 - Luiz | B3: =D16+E16+F16 -> 232 | C3: =B16+C16 -> 57 | D3: =C3/B3 -> 0.24568966 | E3: =AVERAGE('Notas Mai'!$B$2:$B$72) -> 4.9824561 | G3: =E3-F3 -> 4.9824561 | I3: =G3*C3 -> 284
A4: 1004 - Lukas | B4: =D17+E17+F17 -> 431 | C4: =B17+C17 -> 102 | D4: =C4/B4 -> 0.23665893 | E4: =AVERAGE('Notas Mai'!$C$2:$C$72) -> 4.9859155 | G4: =E4-F4 -> 4.9859155 | I4: =G4*C4 -> 508.56338
A5: 1013 - Lucas | B5: =D18+E18+F18 -> 366 | C5: =B18+C18 -> 89 | D5: =C5/B5 -> 0.2431694 | E5: =AVERAGE('Notas Mai'!$D$2:$D$72) -> 4.9788732 | G5: =E5-F5 -> 4.9788732 | I5: =G5*C5 -> 443.11972
A6: 1003 - Pamela | B6: =D19+E19+F19 -> 138 | C6: =B19+C19 -> 44 | D6: =C6/B6 -> 0.31884058 | E6: =AVERAGE('Notas Mai'!$E$2:$E$72) -> 4.9431818 | G6: =E6-F6 -> 4.9431818 | I6: =G6*C6 -> 217.5
A9: TOTAL | B9: =SUM(B2:B7) -> 1551 | C9: =SUM(C2:C7) -> 428 | D9: =C9/B9 -> 0.275951 | E9: =AVERAGE(E2:E7) -> 4.9696346 | G9: =E9-F9 -> 4.9696346
A14: ATENDENTE | B14: QSA | C14: QEA | D14: TS FONE | E14: TE FONE | F14: TE WHATS | G14: WHATS AVALIADOS
A15: 1005 - Dayane | B15: =COUNTIFS(Mai!$B$2:$B$3000,"PSYSTEM_1005",Mai!$E$2:$E$3000,">100",Mai!$L$2:$L$3000,">0") -> 12 | C15: =COUNTIFS(Mai!$C$2:$C$4000,"PSYSTEM_1005",Mai!$E$2:$E$4000,">100",Mai!$L$2:$L$4000,">0")+G15 -> 124 | D15: =COUNTIFS(Mai!$B$2:$B$4000,"PSYSTEM_1005",Mai!$E$2:$E$4000,">100") -> 58 | E15: =COUNTIFS(Mai!$C$2:$C$4000,"PSYSTEM_1005",Mai!$E$2:$E$4000,">100") -> 269 | F15: 57 | G15: 8
A16: 1002 - Luiz | B16: =COUNTIFS(Mai!$B$2:$B$3000,"PSYSTEM_1002",Mai!$E$2:$E$3000,">100",Mai!$L$2:$L$3000,">0") -> 6 | C16: =COUNTIFS(Mai!$C$2:$C$4000,"PSYSTEM_1002",Mai!$E$2:$E$4000,">100",Mai!$L$2:$L$4000,">0")+G16 -> 51 | D16: =COUNTIFS(Mai!$B$2:$B$4000,"PSYSTEM_1002",Mai!$E$2:$E$4000,">100") -> 35 | E16: =COUNTIFS(Mai!$C$2:$C$4000,"PSYSTEM_1002",Mai!$E$2:$E$4000,">100") -> 145 | F16: 52 | G16: 1
A17: 1004 - Lukas | B17: =COUNTIFS(Mai!$B$2:$B$3000,"PSYSTEM_1004",Mai!$E$2:$E$3000,">100",Mai!$L$2:$L$3000,">0") -> 11 | C17: =COUNTIFS(Mai!$C$2:$C$4000,"PSYSTEM_1004",Mai!$E$2:$E$4000,">100",Mai!$L$2:$L$4000,">0")+G17 -> 91 | D17: =COUNTIFS(Mai!$B$2:$B$4000,"PSYSTEM_1004",Mai!$E$2:$E$4000,">100") -> 42 | E17: =COUNTIFS(Mai!$C$2:$C$4000,"PSYSTEM_1004",Mai!$E$2:$E$4000,">100") -> 269 | F17: 120 | G17: 33
A18: 1013 - Lucas | B18: =COUNTIFS(Mai!$B$2:$B$3000,"PSYSTEM_1013",Mai!$E$2:$E$3000,">100",Mai!$L$2:$L$3000,">0") -> 5 | C18: =COUNTIFS(Mai!$C$2:$C$4000,"PSYSTEM_1013",Mai!$E$2:$E$4000,">100",Mai!$L$2:$L$4000,">0")+G18 -> 84 | D18: =COUNTIFS(Mai!$B$2:$B$4000,"PSYSTEM_1013",Mai!$E$2:$E$4000,">100") -> 26 | E18: =COUNTIFS(Mai!$C$2:$C$4000,"PSYSTEM_1013",Mai!$E$2:$E$4000,">100") -> 238 | F18: 102 | G18: 19
A19: 1003 - Pamela | B19: =COUNTIFS(Mai!$B$2:$B$3000,"PSYSTEM_1003",Mai!$E$2:$E$3000,">100",Mai!$L$2:$L$3000,">0") -> 0 | C19: =COUNTIFS(Mai!$C$2:$C$4000,"PSYSTEM_1003",Mai!$E$2:$E$4000,">100",Mai!$L$2:$L$4000,">0")+G19 -> 44 | D19: =COUNTIFS(Mai!$B$2:$B$4000,"PSYSTEM_1003",Mai!$E$2:$E$4000,">100") -> 0 | E19: =COUNTIFS(Mai!$C$2:$C$4000,"PSYSTEM_1003",Mai!$E$2:$E$4000,">100") -> 0 | F19: 138 | G19: 44
A21: QSA = QUANTIDADE DE SAIDAS AVALIADA
A22: QEA = QUANTIDADE DE ENTRADAS AVALIADAS
A23: TS - TOTAL DE SAIDAS
A24: TE - TOTAL DE ENTRADAS

Sheet Jun
A1: date | B1: src | C1: dst | D1: did | E1: duration | F1: talk | G1: status | H1: uniqueid | I1: direction | J1: coust_center | K1: queue_name | L1: nps | M1: Observação
A2: 46203.738 | B2: 44999680829 | C2: PSYSTEM_1002 | D2: 4431268225 | E2: 464 | F2: 262 | G2: ANSWERED | H2: FlexPBX-1782852127.373935 | I2: E | J2: SUPORTE - POWER SYSTEM | K2: PSYSTEM_SUPORTE | L2: 5 | M2: LUIZ | N2: PSYSTEM_1002
A3: 46203.725 | B3: 1128897100 | C3: PSYSTEM_1000 | D3: 4430265054 | E3: 497 | F3: 479 | G3: ANSWERED | H3: FlexPBX-1782851079.373905 | I3: E | J3: SUPORTE - POWER SYSTEM | K3: PSYSTEM_COMERCIAL | M3: EDERSON | N3: PSYSTEM_1000
A4: 46203.715 | B4: 44998039090 | C4: 4430265054 | D4: 4430265054 | E4: 29 | F4: 29 | G4: NO ANSWER | H4: FlexPBX-1782850143.373850 | I4: E | J4: GERAL - POWER SYSTEM | K4: PSYSTEM_SUPORTE
A5: 46203.709 | B5: 41997840159 | C5: PSYSTEM_1002 | D5: 4430265054 | E5: 1041 | F5: 845 | G5: ANSWERED | H5: FlexPBX-1782849625.373738 | I5: E | J5: SUPORTE - POWER SYSTEM | K5: PSYSTEM_SUPORTE | L5: 5 | M5: LUIZ | N5: PSYSTEM_1002
A6: 46203.705 | B6: 6434534421 | C6: PSYSTEM_1013 | D6: 4430265054 | E6: 2364 | F6: 2296 | G6: ANSWERED | H6: FlexPBX-1782849343.373684 | I6: E | J6: SUPORTE - POWER SYSTEM | K6: PSYSTEM_SUPORTE | L6: 5 | M6: LUCAS | N6: PSYSTEM_1013
A7: 46203.703 | B7: 18996991511 | C7: PSYSTEM_1004 | D7: 4430265054 | E7: 236 | F7: 127 | G7: ANSWERED | H7: FlexPBX-1782849166.373640 | I7: E | J7: SUPORTE - POWER SYSTEM | K7: PSYSTEM_SUPORTE | L7: 5 | M7: LUKAS | N7: PSYSTEM_1004
A8: 46203.701 | B8: 44999752325 | C8: PSYSTEM_1002 | D8: 4430265054 | E8: 470 | F8: 393 | G8: ANSWERED | H8: FlexPBX-1782849002.373588 | I8: E | J8: SUPORTE - POWER SYSTEM | K8: PSYSTEM_SUPORTE | L8: 5 | M8: LUIZ | N8: PSYSTEM_1002
A9: 46203.697 | B9: 44997650834 | C9: PSYSTEM_1005 | D9: 4430265054 | E9: 790 | F9: 773 | G9: ANSWERED | H9: FlexPBX-1782848587.373566 | I9: E | J9: SUPORTE - POWER SYSTEM | K9: PSYSTEM_SUPORTE | L9: 5 | M9: DAYANE | N9: PSYSTEM_1005
A10: 46203.682 | B10: 44997215491 | C10: PSYSTEM_1004 | D10: 4430265054 | E10: 1388 | F10: 1131 | G10: ANSWERED | H10: FlexPBX-1782847361.373340 | I10: E | J10: SUPORTE - POWER SYSTEM | K10: PSYSTEM_SUPORTE | L10: 5 | M10: LUKAS | N10: PSYSTEM_1004
A11: 46203.673 | B11: 4432325260 | C11: PSYSTEM_1004 | D11: 4430265054 | E11: 269 | F11: 170 | G11: ANSWERED | H11: FlexPBX-1782846584.373260 | I11: E | J11: SUPORTE - POWER SYSTEM | K11: PSYSTEM_SUPORTE | M11: LUKAS | N11: PSYSTEM_1004
A12: 46203.672 | B12: PSYSTEM_1000 | C12: 4434221055 | E12: 715 | F12: 705 | G12: ANSWERED | H12: FlexPBX-1782846418.373252 | I12: S | J12: SUPORTE - POWER SYSTEM | M12: EDERSON | N12: PSYSTEM_1000
A13: 46203.658 | B13: 4330261969 | C13: PSYSTEM_1004 | D13: 4430265054 | E13: 114 | F13: 54 | G13: ANSWERED | H13: FlexPBX-1782845219.373196 | I13: E | J13: SUPORTE - POWER SYSTEM | K13: PSYSTEM_SUPORTE | M13: LUKAS | N13: PSYSTEM_1004
A14: 46203.652 | B14: 44999654761 | C14: PSYSTEM_1002 | D14: 4430265054 | E14: 338 | F14: 152 | G14: ANSWERED | H14: FlexPBX-1782844705.373042 | I14: E | J14: SUPORTE - POWER SYSTEM | K14: PSYSTEM_SUPORTE | M14: LUIZ | N14: PSYSTEM_1002
A15: 46203.643 | B15: PSYSTEM_1005 | C15: 1131515685 | E15: 411 | F15: 406 | G15: ANSWERED | H15: FlexPBX-1782843965.373022 | I15: S | J15: SUPORTE - POWER SYSTEM | M15: DAYANE | N15: PSYSTEM_1005
A16: 46203.642 | B16: 1131515685 | C16: PSYSTEM_1005 | D16: 4430265054 | E16: 24 | F16: 4 | G16: ANSWERED | H16: FlexPBX-1782843887.373000 | I16: E | J16: SUPORTE - POWER SYSTEM | K16: PSYSTEM_SUPORTE | M16: DAYANE | N16: PSYSTEM_1005
A17: 46203.641 | B17: 1131515685 | C17: PSYSTEM_1005 | D17: 4430265054 | E17: 115 | F17: 8 | G17: ANSWERED | H17: FlexPBX-1782843745.372930 | I17: E | J17: SUPORTE - POWER SYSTEM | K17: PSYSTEM_SUPORTE | M17: DAYANE | N17: PSYSTEM_1005
A18: 46203.638 | B18: PSYSTEM_1002 | C18: 41991740047 | E18: 51 | F18: 32 | G18: ANSWERED | H18: FlexPBX-1782843525.372884 | I18: S | J18: SUPORTE - POWER SYSTEM | M18: LUIZ | N18: PSYSTEM_1002
A19: 46203.636 | B19: 41999865917 | C19: PSYSTEM_1005 | D19: 4430265054 | E19: 250 | F19: 230 | G19: ANSWERED | H19: FlexPBX-1782843344.372834 | I19: E | J19: SUPORTE - POWER SYSTEM | K19: PSYSTEM_SUPORTE | L19: 5 | M19: DAYANE | N19: PSYSTEM_1005
A20: 46203.631 | B20: 1131515685 | C20: 4430265054 | D20: 4430265054 | E20: 17 | F20: 16 | G20: NO ANSWER | H20: FlexPBX-1782842936.372734 | I20: E | J20: GERAL - POWER SYSTEM
A21: 46203.631 | B21: 44998039090 | C21: PSYSTEM_1002 | D21: 4430265054 | E21: 430 | F21: 322 | G21: ANSWERED | H21: FlexPBX-1782842928.372725 | I21: E | J21: SUPORTE - POWER SYSTEM | K21: PSYSTEM_SUPORTE | M21: LUIZ | N21: PSYSTEM_1002
A22: 46203.631 | B22: 62991155122 | C22: PSYSTEM_1004 | D22: 4430265054 | E22: 1194 | F22: 1165 | G22: ANSWERED | H22: FlexPBX-1782842896.372683 | I22: E | J22: SUPORTE - POWER SYSTEM | K22: PSYSTEM_SUPORTE | M22: LUKAS | N22: PSYSTEM_1004
A23: 46203.629 | B23: 44998039090 | C23: 4430265054 | D23: 4430265054 | E23: 144 | F23: 144 | G23: NO ANSWER | H23: FlexPBX-1782842762.372586 | I23: E | J23: GERAL - POWER SYSTEM | K23: PSYSTEM_SUPORTE
A24: 46203.627 | B24: 64984043469 | C24: 4430265054 | D24: 4430265054 | E24: 6 | F24: 5 | G24: NO ANSWER | H24: FlexPBX-1782842584.372575 | I24: E | J24: GERAL - POWER SYSTEM
A25: 46203.624 | B25: 4432226677 | C25: PSYSTEM_1002 | D25: 4430265054 | E25: 527 | F25: 460 | G25: ANSWERED | H25: FlexPBX-1782842342.372507 | I25: E | J25: SUPORTE - POWER SYSTEM | K25: PSYSTEM_SUPORTE | L25: 5 | M25: LUIZ | N25: PSYSTEM_1002
A26: 46203.623 | B26: 91985176746 | C26: PSYSTEM_1013 | D26: 4430265054 | E26: 364 | F26: 265 | G26: ANSWERED | H26: FlexPBX-1782842227.372443 | I26: E | J26: SUPORTE - POWER SYSTEM | K26: PSYSTEM_SUPORTE | M26: LUCAS | N26: PSYSTEM_1013
A27: 46203.616 | B27: PSYSTEM_1010 | C27: 4436351414 | E27: 185 | F27: 174 | G27: ANSWERED | H27: FlexPBX-1782841584.372403 | I27: S | J27: GERAL - POWER SYSTEM | M27: CLEBER | N27: PSYSTEM_1010
A28: 46203.615 | B28: PSYSTEM_1010 | C28: 4436351414 | E28: 7 | F28: 6 | G28: ANSWERED | H28: FlexPBX-1782841575.372389 | I28: S | J28: GERAL - POWER SYSTEM | M28: CLEBER | N28: PSYSTEM_1010
A29: 46203.612 | B29: PSYSTEM_1002 | C29: 4430266744 | E29: 665 | F29: 656 | G29: ANSWERED | H29: FlexPBX-1782841281.372358 | I29: S | J29: SUPORTE - POWER SYSTEM | L29: 5 | M29: LUIZ | N29: PSYSTEM_1002
A30: 46203.612 | B30: PSYSTEM_1002 | C30: 4430266744 | E30: 14 | F30: 13 | G30: ANSWERED | H30: FlexPBX-1782841273.372344 | I30: S | J30: SUPORTE - POWER SYSTEM | M30: LUIZ | N30: PSYSTEM_1002
A31: 46203.611 | B31: 4430315826 | C31: PSYSTEM_1000 | D31: 4430265054 | E31: 682 | F31: 682 | G31: ANSWERED | H31: FlexPBX-1782841225.372337 | I31: E | J31: SUPORTE - POWER SYSTEM | K31: PSYSTEM_SUPORTE | L31: 5 | M31: EDERSON | N31: PSYSTEM_1000
A32: 46203.61 | B32: 62991155122 | C32: PSYSTEM_1013 | D32: 4430265054 | E32: 218 | F32: 156 | G32: ANSWERED | H32: FlexPBX-1782841094.372289 | I32: E | J32: SUPORTE - POWER SYSTEM | K32: PSYSTEM_SUPORTE | M32: LUCAS | N32: PSYSTEM_1013
A33: 46203.609 | B33: 43988030048 | C33: PSYSTEM_1005 | D33: 4430265054 | E33: 1413 | F33: 1347 | G33: ANSWERED | H33: FlexPBX-1782841056.372252 | I33: E | J33: SUPORTE - POWER SYSTEM | K33: PSYSTEM_SUPORTE | M33: DAYANE | N33: PSYSTEM_1005
A34: 46203.608 | B34: 62994086124 | C34: PSYSTEM_1004 | D34: 4430265054 | E34: 1277 | F34: 1094 | G34: ANSWERED | H34: FlexPBX-1782840914.372145 | I34: E | J34: SUPORTE - POWER SYSTEM | K34: PSYSTEM_SUPORTE | L34: 5 | M34: LUKAS | N34: PSYSTEM_1004
A35: 46203.607 | B35: 62994086124 | C35: 4430265054 | D35: 4430265054 | E35: 33 | F35: 32 | G35: NO ANSWER | H35: FlexPBX-1782840832.372108 | I35: E | J35: GERAL - POWER SYSTEM | K35: PSYSTEM_SUPORTE
A36: 46203.599 | B36: 11947305571 | C36: PSYSTEM_1000 | D36: 4430265054 | E36: 489 | F36: 325 | G36: ANSWERED | H36: FlexPBX-1782840177.371957 | I36: E | J36: SUPORTE - POWER SYSTEM | K36: PSYSTEM_SUPORTE | M36: EDERSON | N36: PSYSTEM_1000
A37: 46203.599 | B37: 4430266744 | C37: PSYSTEM_1002 | D37: 4430265054 | E37: 532 | F37: 363 | G37: ANSWERED | H37: FlexPBX-1782840171.371954 | I37: E | J37: SUPORTE - POWER SYSTEM | K37: PSYSTEM_SUPORTE | M37: LUIZ | N37: PSYSTEM_1002
A38: 46203.594 | B38: 11966416756 | C38: PSYSTEM_1013 | D38: 4431268225 | E38: 202 | F38: 161 | G38: ANSWERED | H38: FlexPBX-1782839761.371922 | I38: E | J38: SUPORTE - POWER SYSTEM | K38: PSYSTEM_SUPORTE | M38: LUCAS | N38: PSYSTEM_1013
A39: 46203.586 | B39: 4430317020 | C39: PSYSTEM_1005 | D39: 4430265054 | E39: 1516 | F39: 1435 | G39: ANSWERED | H39: FlexPBX-1782838988.371864 | I39: E | J39: SUPORTE - POWER SYSTEM | K39: PSYSTEM_SUPORTE | M39: DAYANE | N39: PSYSTEM_1005
A40: 46203.584 | B40: 44991668902 | C40: PSYSTEM_1013 | D40: 4430265054 | E40: 218 | F40: 156 | G40: ANSWERED | H40: FlexPBX-1782838818.371824 | I40: E | J40: SUPORTE - POWER SYSTEM | K40: PSYSTEM_SUPORTE | M40: LUCAS | N40: PSYSTEM_1013
...

Sheet Notas Jun
A1: 1005 - Dayane | B1: 1002 - Luiz | C1: 1004 - Lukas | D1: 1013 - Lucas | E1: 1001 - Gabriel
A2: 5 | B2: 5 | C2: 5 | D2: 5
A3: 5 | B3: 5 | C3: 5 | D3: 5
A4: 5 | B4: 5 | C4: 5 | D4: 5
A5: 5 | B5: 5 | C5: 5 | D5: 5
A6: 5 | B6: 5 | C6: 5 | D6: 5
A7: 5 | B7: 5 | C7: 5 | D7: 5
A8: 5 | B8: 5 | C8: 5 | D8: 5
A9: 5 | B9: 5 | C9: 5 | D9: 5
A10: 5 | B10: 5 | C10: 5 | D10: 5
A11: 5 | B11: 5 | C11: 5 | D11: 5
A12: 5 | B12: 5 | C12: 5 | D12: 5
A13: 5 | B13: 5 | C13: 5 | D13: 5
... A59: 5 | B59: 5 | C59: 4.5 | D59: 5
A60: 5 | B60: 5 | D60: 5
A61: 5 | B61: 5 | D61: 5
A62: 5 | B62: 5 | D62: 5
A63: 4 | B63: 5 | D63: 5
A64: 3 | B64: 4 | D64: 5
A65: 5 | B65: 5 | D65: 5
A66: 5 | B66: 4 | D66: 5
A67: 5 | B67: 5 | D67: 5
A68: 5 | B68: 4 | D68: 5
A69: 5 | B69: 5 | D69: 5
A70: 5 | B70: 4 | D70: 5
A71: 5 | B71: 5 | D71: 5
... A106: 5 | B106: 5 | D106: 4
A107: 5 | B107: 5
A108: 5 | B108: 5
A109: 5 | B109: 5
A110: 5 | B110: 5
A111: 5 | B111: 5
A112: 5 | B112: 5
A113: 5 | B113: 5
A114: 4.5 | B114: 5
A115: 4.5 | B115: 5
B116: 5
B117: 5
B118: 5
B119: 5
...

Sheet Nps Jun
A1: ATENDENTE | B1: QTD ATENDIMENTOS | C1: QTD AVALIADOS | D1: PERCENTUAL AVALIAÇÃO | E1: MÉDIA NOTAS | F1: DESCONTOS AVALIAÇÕES | G1: MÉDIA NOTAS FINAL | I1: PONTUAÇÃO CAIXINHA
A2: 1005 - Dayane | B2: =D15+E15+F15 -> 410 | C2: =B15+C15 -> 116 | D2: =C2/B2 -> 0.28292683 | E2: =AVERAGE('Notas Jun'!$A$2:$A$200) -> 4.9210526 | G2: =E2-F2 -> 4.9210526 | I2: =G2*C2 -> 570.84211
A3: 1002 - Luiz | B3: =D16+E16+F16 -> 429 | C3: =B16+C16 -> 153 | D3: =C3/B3 -> 0.35664336 | E3: =AVERAGE('Notas Jun'!$B$2:$B$200) -> 4.9253247 | G3: =E3-F3 -> 4.9253247 | I3: =G3*C3 -> 753.57468
A4: 1004 - Lukas | B4: =D17+E17+F17 -> 271 | C4: =B17+C17 -> 59 | D4: =C4/B4 -> 0.21771218 | E4: =AVERAGE('Notas Jun'!$C$2:$C$200) -> 4.9913793 | G4: =E4-F4 -> 4.9913793 | I4: =G4*C4 -> 294.49138
A5: 1013 - Lucas | B5: =D18+E18+F18 -> 467 | C5: =B18+C18 -> 113 | D5: =C5/B5 -> 0.24197002 | E5: =AVERAGE('Notas Jun'!$D$2:$D$200) -> 4.9428571 | G5: =E5-F5 -> 4.9428571 | I5: =G5*C5 -> 558.54286
A9: TOTAL | B9: =SUM(B2:B7) -> 1577 | C9: =SUM(C2:C7) -> 441 | D9: =C9/B9 -> 0.2796449 | E9: =AVERAGE(E2:E7) -> 4.9451534 | G9: =E9-F9 -> 4.9451534
A14: ATENDENTE | B14: QSA | C14: QEA | D14: TS FONE | E14: TE FONE | F14: TE WHATS | G14: WHATS AVALIADOS
A15: 1005 - Dayane | B15: =COUNTIFS(Jun!$B$2:$B$3000,"PSYSTEM_1005",Jun!$E$2:$E$3000,">100",Jun!$L$2:$L$3000,">0") -> 9 | C15: =COUNTIFS(Jun!$C$2:$C$4000,"PSYSTEM_1005",Jun!$E$2:$E$4000,">100",Jun!$L$2:$L$4000,">0")+G15 -> 107 | D15: =COUNTIFS(Jun!$B$2:$B$4000,"PSYSTEM_1005",Jun!$E$2:$E$4000,">100") -> 54 | E15: =COUNTIFS(Jun!$C$2:$C$4000,"PSYSTEM_1005",Jun!$E$2:$E$4000,">100") -> 254 | F15: 102 | G15: 23
A16: 1002 - Luiz | B16: =COUNTIFS(Jun!$B$2:$B$3000,"PSYSTEM_1002",Jun!$E$2:$E$3000,">100",Jun!$L$2:$L$3000,">0") -> 21 | C16: =COUNTIFS(Jun!$C$2:$C$4000,"PSYSTEM_1002",Jun!$E$2:$E$4000,">100",Jun!$L$2:$L$4000,">0")+G16 -> 132 | D16: =COUNTIFS(Jun!$B$2:$B$4000,"PSYSTEM_1002",Jun!$E$2:$E$4000,">100") -> 45 | E16: =COUNTIFS(Jun!$C$2:$C$4000,"PSYSTEM_1002",Jun!$E$2:$E$4000,">100") -> 269 | F16: 115 | G16: 15
A17: 1004 - Lukas | B17: =COUNTIFS(Jun!$B$2:$B$3000,"PSYSTEM_1004",Jun!$E$2:$E$3000,">100",Jun!$L$2:$L$3000,">0") -> 1 | C17: =COUNTIFS(Jun!$C$2:$C$4000,"PSYSTEM_1004",Jun!$E$2:$E$4000,">100",Jun!$L$2:$L$4000,">0")+G17 -> 58 | D17: =COUNTIFS(Jun!$B$2:$B$4000,"PSYSTEM_1004",Jun!$E$2:$E$4000,">100") -> 14 | E17: =COUNTIFS(Jun!$C$2:$C$4000,"PSYSTEM_1004",Jun!$E$2:$E$4000,">100") -> 164 | F17: 93 | G17: 16
A18: 1013 - Lucas | B18: =COUNTIFS(Jun!$B$2:$B$3000,"PSYSTEM_1013",Jun!$E$2:$E$3000,">100",Jun!$L$2:$L$3000,">0") -> 4 | C18: =COUNTIFS(Jun!$C$2:$C$4000,"PSYSTEM_1013",Jun!$E$2:$E$4000,">100",Jun!$L$2:$L$4000,">0")+G18 -> 109 | D18: =COUNTIFS(Jun!$B$2:$B$4000,"PSYSTEM_1013",Jun!$E$2:$E$4000,">100") -> 16 | E18: =COUNTIFS(Jun!$C$2:$C$4000,"PSYSTEM_1013",Jun!$E$2:$E$4000,">100") -> 243 | F18: 208 | G18: 36
A21: QSA = QUANTIDADE DE SAIDAS AVALIADA
A22: QEA = QUANTIDADE DE ENTRADAS AVALIADAS
A23: TS - TOTAL DE SAIDAS
A24: TE - TOTAL DE ENTRADAS

Sheet Notas Trim
A1: 1005 - Dayane | B1: 1002 - Luiz | C1: 1004 - Lukas | D1: 1013 - Lucas | E1: 1001 - Gabriel
A2: 5 | B2: 5 | C2: 5 | D2: 5
A3: 5 | B3: 5 | C3: 5 | D3: 5
A4: 5 | B4: 5 | C4: 5 | D4: 5
A5: 5 | B5: 5 | C5: 5 | D5: 5
A6: 5 | B6: 5 | C6: 5 | D6: 5
A7: 5 | B7: 5 | C7: 5 | D7: 5
A8: 5 | B8: 5 | C8: 5 | D8: 5
A9: 5 | B9: 5 | C9: 5 | D9: 5
A10: 5 | B10: 5 | C10: 5 | D10: 5
A11: 5 | B11: 5 | C11: 4 | D11: 5
A12: 5 | B12: 5 | C12: 5 | D12: 5
A13: 5 | B13: 5 | C13: 5 | D13: 5
... A265: 5 | B265: 5 | C265: 5 | D265: 4
A266: 5 | B266: 5 | C266: 5
A267: 5 | B267: 4 | C267: 5
A268: 5 | B268: 5 | C268: 5
A269: 5 | B269: 5 | C269: 5
A270: 5 | B270: 5 | C270: 4.5
A271: 5 | B271: 5
A272: 4 | B272: 5
A273: 4 | B273: 5
A274: 5 | B274: 5
A275: 5 | B275: 5
A276: 5 | B276: 5
A277: 5 | B277: 5
A278: 5 | B278: 5
A279: 5 | B279: 5
A280: 5 | B280: 5
A281: 5 | B281: 5
A282: 5 | B282: 5
... A327: 5 | B327: 4
A328: 5
A329: 5
A330: 5
A331: 5
A332: 5
A333: 5
A334: 5
A335: 5
...

Sheet NPS Trim
A1: ATENDENTE | B1: QTD ATENDIMENTOS | C1: QTD AVALIADOS | D1: PERCENTUAL AVALIAÇÃO | E1: MÉDIA NOTAS | F1: DESCONTOS AVALIAÇÕES | G1: MÉDIA NOTAS FINAL | J1: BONIFICAÇÃO
A2: 1005 - Dayane | B2: =D15+E15+F15 -> 1168 | C2: =B15+C15 -> 360 | D2: =C2/B2 -> 0.30821918 | E2: =AVERAGE('Notas Trim'!A2:A900) -> 4.9497207 | G2: =E2-F2 -> 4.9497207 | J2: =IF((((E15+B15+F15)*G2)/10)>500,500,((E15+B15+F15)*G2/10)) -> 500
A3: 1002 - Luiz | B3: =D16+E16+F16 -> 1009 | C3: =B16+C16 -> 325 | D3: =C3/B3 -> 0.32210109 | E3: =AVERAGE('Notas Trim'!B2:B900) -> 4.9493865 | G3: =E3-F3 -> 4.9493865 | J3: =IF((((E16+B16+F16)*G3)/10)>500,500,((E16+B16+F16)*G3/10)) -> 451.38405
A4: 1004 - Lukas | B4: =D17+E17+F17 -> 1048 | C4: =B17+C17 -> 270 | D4: =C4/B4 -> 0.25763359 | E4: =AVERAGE('Notas Trim'!C2:C900) -> 4.9758364 | G4: =E4-F4 -> 4.9758364 | J4: =IF((((E17+B17+F17)*G4)/10)>500,500,((E17+B17+F17)*G4/10)) -> 482.65613
A5: 1013 - Lucas | B5: =D18+E18+F18 -> 1150 | C5: =B18+C18 -> 272 | D5: =C5/B5 -> 0.23652174 | E5: =AVERAGE('Notas Trim'!D2:D900) -> 4.9583333 | G5: =E5-F5 -> 4.9583333 | J5: =IF((((E18+B18+F18)*G5)/10)>500,500,((E18+B18+F18)*G5/10)) -> 500
J6: =IF((((E19+B19+F19)*G6)/10)>500,500,((E19+B19+F19)*G6/10)) -> 0
A9: TOTAL | B9: =SUM(B2:B7) -> 4375 | C9: =SUM(C2:C7) -> 1227 | D9: =C9/B9 -> 0.28045714 | E9: =AVERAGE(E2:E7) -> 4.9583192 | G9: =E9-F9 -> 4.9583192 | J9: =SUM(J2:J7) -> 1934.0402
A14: ATENDENTE | B14: QSA | C14: QEA | D14: TS FONE | E14: TE FONE | F14: TE WHATS | G14: WHATS AVALIADOS
A15: 1005 - Dayane | B15: ='Nps Abr'!B15+'Nps Mai'!B15+'Nps Jun'!B15 -> 38 | C15: ='Nps Abr'!C15+'Nps Mai'!C15+'Nps Jun'!C15 -> 322 | D15: ='Nps Abr'!D15+'Nps Mai'!D15+'Nps Jun'!D15 -> 178 | E15: ='Nps Abr'!E15+'Nps Mai'!E15+'Nps Jun'!E15 -> 759 | F15: ='Nps Abr'!F15+'Nps Mai'!F15+'Nps Jun'!F15 -> 231 | G15: ='Nps Abr'!G15+'Nps Mai'!G15+'Nps Jun'!G15 -> 40
A16: 1002 - Luiz | B16: ='Nps Abr'!B16+'Nps Mai'!B16+'Nps Jun'!B16 -> 36 | C16: ='Nps Abr'!C16+'Nps Mai'!C16+'Nps Jun'!C16 -> 289 | D16: ='Nps Abr'!D16+'Nps Mai'!D16+'Nps Jun'!D16 -> 133 | E16: ='Nps Abr'!E16+'Nps Mai'!E16+'Nps Jun'!E16 -> 612 | F16: ='Nps Abr'!F16+'Nps Mai'!F16+'Nps Jun'!F16 -> 264 | G16: ='Nps Abr'!G16+'Nps Mai'!G16+'Nps Jun'!G16 -> 33
A17: 1004 - Lukas | B17: ='Nps Abr'!B17+'Nps Mai'!B17+'Nps Jun'!B17 -> 22 | C17: ='Nps Abr'!C17+'Nps Mai'!C17+'Nps Jun'!C17 -> 248 | D17: ='Nps Abr'!D17+'Nps Mai'!D17+'Nps Jun'!D17 -> 100 | E17: ='Nps Abr'!E17+'Nps Mai'!E17+'Nps Jun'!E17 -> 662 | F17: ='Nps Abr'!F17+'Nps Mai'!F17+'Nps Jun'!F17 -> 286 | G17: ='Nps Abr'!G17+'Nps Mai'!G17+'Nps Jun'!G17 -> 66
A18: 1013 - Lucas | B18: ='Nps Abr'!B18+'Nps Mai'!B18+'Nps Jun'!B18 -> 11 | C18: ='Nps Abr'!C18+'Nps Mai'!C18+'Nps Jun'!C18 -> 261 | D18: ='Nps Abr'!D18+'Nps Mai'!D18+'Nps Jun'!D18 -> 60 | E18: ='Nps Abr'!E18+'Nps Mai'!E18+'Nps Jun'!E18 -> 648 | F18: ='Nps Abr'!F18+'Nps Mai'!F18+'Nps Jun'!F18 -> 442 | G18: ='Nps Abr'!G18+'Nps Mai'!G18+'Nps Jun'!G18 -> 75
A21: QSA = QUANTIDADE DE SAIDAS AVALIADA
A22: QEA = QUANTIDADE DE ENTRADAS AVALIADAS
A23: TS - TOTAL DE SAIDAS
A24: TE - TOTAL DE ENTRADAS
